---
title: ChaiScript-d77921f1b5aa01e8acbb1f5bed2a540ddc6c45e1-x86_64-Linux-Ubuntu-14.04-clang-3.5-ThreadSanitizer
permalink: ChaiScript-d77921f1b5aa01e8acbb1f5bed2a540ddc6c45e1-x86_64-Linux-Ubuntu-14.04-clang-3.5-ThreadSanitizer.html
tags: data
layout: ci_results
date: 2015-05-01 04:48:35
unhandled_failure: false
build_error_count: 0
build_warning_count: 0
package_error_count: 0
package_warning_count: 0
test_count: 346
test_passed_count: 2
repository: ChaiScript/ChaiScript
compiler: clang
compiler_version: 3.5
architecture: 
os: Linux
os_release: Ubuntu-14.04
is_release: false
release_packaged: false
packaging_skipped: true
package_name: 
tag_name: 
commit_sha: d77921f1b5aa01e8acbb1f5bed2a540ddc6c45e1
branch_name: parsing_reorg
test_run: true
pull_request_issue_id: ""
pull_request_base_repository: 
pull_request_base_ref: 
device_id: x86_64-Linux-Ubuntu-14.04-clang-3.5-ThreadSanitizer
pending: false
analyze_only: false
build_time: 208.206357227
test_time: 28.554147232
package_time: 
install_time: 
results_repository: ChaiScript/ChaiScript-BuildResults
machine_name: jason-VirtualBox
machine_ip: 10.0.2.15
coverage_enabled: false
coverage_pass_limit: 90
coverage_warn_limit: 75
coverage_lines: 0
coverage_total_lines: 0
coverage_functions: 0
coverage_total_functions: 0
coverage_url: 
asset_url: 
---

{
  "build_results": [

  ],
  "test_results": [
    {
      "name": "3.x/bind.chai",
      "status": "failed",
      "time": "0.420993",
      "output": "terminate called after throwing an instance of 'std::invalid_argument'\n  what():  stod\n",
      "parsed_errors": [

      ]
    },
    {
      "name": "3.x/bind2.chai",
      "status": "failed",
      "time": "0.437805",
      "output": "terminate called after throwing an instance of 'std::invalid_argument'\n  what():  stod\n",
      "parsed_errors": [

      ]
    },
    {
      "name": "3.x/break_while.chai",
      "status": "failed",
      "time": "0.445799",
      "output": "terminate called after throwing an instance of 'std::invalid_argument'\n  what():  stod\n",
      "parsed_errors": [

      ]
    },
    {
      "name": "version_check",
      "status": "failed",
      "time": "0.461093",
      "output": "terminate called after throwing an instance of 'std::invalid_argument'\n  what():  stod\n",
      "parsed_errors": [

      ]
    },
    {
      "name": "3.x/bool_not.chai",
      "status": "failed",
      "time": "0.563228",
      "output": "terminate called after throwing an instance of 'std::invalid_argument'\n  what():  stod\n",
      "parsed_errors": [

      ]
    },
    {
      "name": "3.x/block_start.chai",
      "status": "failed",
      "time": "0.567399",
      "output": "terminate called after throwing an instance of 'std::invalid_argument'\n  what():  stod\n",
      "parsed_errors": [

      ]
    },
    {
      "name": "3.x/assign_const.chai",
      "status": "failed",
      "time": "0.572728",
      "output": "terminate called after throwing an instance of 'std::invalid_argument'\n  what():  stod\n",
      "parsed_errors": [

      ]
    },
    {
      "name": "3.x/collate.chai",
      "status": "failed",
      "time": "0.336094",
      "output": "terminate called after throwing an instance of 'std::invalid_argument'\n  what():  stod\n",
      "parsed_errors": [

      ]
    },
    {
      "name": "3.x/char_init.chai",
      "status": "failed",
      "time": "0.350902",
      "output": "terminate called after throwing an instance of 'std::invalid_argument'\n  what():  stod\n",
      "parsed_errors": [

      ]
    },
    {
      "name": "3.x/compare_gt.chai",
      "status": "failed",
      "time": "0.646566",
      "output": "terminate called after throwing an instance of 'std::invalid_argument'\n  what():  stod\n",
      "parsed_errors": [

      ]
    },
    {
      "name": "3.x/classification.chai",
      "status": "failed",
      "time": "0.651666",
      "output": "terminate called after throwing an instance of 'std::invalid_argument'\n  what():  stod\n",
      "parsed_errors": [

      ]
    },
    {
      "name": "3.x/const_range_test.chai",
      "status": "failed",
      "time": "0.310124",
      "output": "terminate called after throwing an instance of 'std::invalid_argument'\n  what():  stod\n",
      "parsed_errors": [

      ]
    },
    {
      "name": "3.x/convert_double_string.chai",
      "status": "failed",
      "time": "0.522589",
      "output": "terminate called after throwing an instance of 'std::invalid_argument'\n  what():  stod\n",
      "parsed_errors": [

      ]
    },
    {
      "name": "3.x/concat.chai",
      "status": "failed",
      "time": "0.528165",
      "output": "terminate called after throwing an instance of 'std::invalid_argument'\n  what():  stod\n",
      "parsed_errors": [

      ]
    },
    {
      "name": "3.x/compare_lt.chai",
      "status": "failed",
      "time": "0.530508",
      "output": "terminate called after throwing an instance of 'std::invalid_argument'\n  what():  stod\n",
      "parsed_errors": [

      ]
    },
    {
      "name": "3.x/convert_int_string.chai",
      "status": "failed",
      "time": "0.314521",
      "output": "terminate called after throwing an instance of 'std::invalid_argument'\n  what():  stod\n",
      "parsed_errors": [

      ]
    },
    {
      "name": "3.x/convert_string_double.chai",
      "status": "failed",
      "time": "0.327474",
      "output": "terminate called after throwing an instance of 'std::invalid_argument'\n  what():  stod\n",
      "parsed_errors": [

      ]
    },
    {
      "name": "3.x/convert_string_int.chai",
      "status": "failed",
      "time": "0.325193",
      "output": "terminate called after throwing an instance of 'std::invalid_argument'\n  what():  stod\n",
      "parsed_errors": [

      ]
    },
    {
      "name": "3.x/drop_while.chai",
      "status": "failed",
      "time": "0.309844",
      "output": "terminate called after throwing an instance of 'std::invalid_argument'\n  what():  stod\n",
      "parsed_errors": [

      ]
    },
    {
      "name": "3.x/deep_array_lookup.chai",
      "status": "failed",
      "time": "0.625773",
      "output": "terminate called after throwing an instance of 'std::invalid_argument'\n  what():  stod\n",
      "parsed_errors": [

      ]
    },
    {
      "name": "3.x/dispatch_functions.chai",
      "status": "failed",
      "time": "0.316377",
      "output": "terminate called after throwing an instance of 'std::invalid_argument'\n  what():  stod\n",
      "parsed_errors": [

      ]
    },
    {
      "name": "3.x/drop.chai",
      "status": "failed",
      "time": "0.334075",
      "output": "terminate called after throwing an instance of 'std::invalid_argument'\n  what():  stod\n",
      "parsed_errors": [

      ]
    },
    {
      "name": "3.x/empty.chai",
      "status": "failed",
      "time": "0.63142",
      "output": "terminate called after throwing an instance of 'std::invalid_argument'\n  what():  stod\n",
      "parsed_errors": [

      ]
    },
    {
      "name": "3.x/eval_error.chai",
      "status": "failed",
      "time": "0.34647",
      "output": "terminate called after throwing an instance of 'std::invalid_argument'\n  what():  stod\n",
      "parsed_errors": [

      ]
    },
    {
      "name": "3.x/equ_shortform.chai",
      "status": "failed",
      "time": "0.350786",
      "output": "terminate called after throwing an instance of 'std::invalid_argument'\n  what():  stod\n",
      "parsed_errors": [

      ]
    },
    {
      "name": "3.x/filter.chai",
      "status": "failed",
      "time": "0.304717",
      "output": "terminate called after throwing an instance of 'std::invalid_argument'\n  what():  stod\n",
      "parsed_errors": [

      ]
    },
    {
      "name": "3.x/eval.chai",
      "status": "failed",
      "time": "0.65834",
      "output": "terminate called after throwing an instance of 'std::invalid_argument'\n  what():  stod\n",
      "parsed_errors": [

      ]
    },
    {
      "name": "3.x/even.chai",
      "status": "failed",
      "time": "0.651469",
      "output": "terminate called after throwing an instance of 'std::invalid_argument'\n  what():  stod\n",
      "parsed_errors": [

      ]
    },
    {
      "name": "3.x/exception.chai",
      "status": "failed",
      "time": "0.64591",
      "output": "terminate called after throwing an instance of 'std::invalid_argument'\n  what():  stod\n",
      "parsed_errors": [

      ]
    },
    {
      "name": "3.x/exception_finally.chai",
      "status": "failed",
      "time": "0.327069",
      "output": "terminate called after throwing an instance of 'std::invalid_argument'\n  what():  stod\n",
      "parsed_errors": [

      ]
    },
    {
      "name": "3.x/float.chai",
      "status": "failed",
      "time": "0.336836",
      "output": "terminate called after throwing an instance of 'std::invalid_argument'\n  what():  stod\n",
      "parsed_errors": [

      ]
    },
    {
      "name": "3.x/exception_guards.chai",
      "status": "failed",
      "time": "0.644304",
      "output": "terminate called after throwing an instance of 'std::invalid_argument'\n  what():  stod\n",
      "parsed_errors": [

      ]
    },
    {
      "name": "3.x/foldl.chai",
      "status": "failed",
      "time": "0.333162",
      "output": "terminate called after throwing an instance of 'std::invalid_argument'\n  what():  stod\n",
      "parsed_errors": [

      ]
    },
    {
      "name": "3.x/for_each.chai",
      "status": "failed",
      "time": "0.355686",
      "output": "terminate called after throwing an instance of 'std::invalid_argument'\n  what():  stod\n",
      "parsed_errors": [

      ]
    },
    {
      "name": "3.x/for_each_range.chai",
      "status": "failed",
      "time": "0.36766",
      "output": "terminate called after throwing an instance of 'std::invalid_argument'\n  what():  stod\n",
      "parsed_errors": [

      ]
    },
    {
      "name": "3.x/for_each_retro.chai",
      "status": "failed",
      "time": "0.467075",
      "output": "terminate called after throwing an instance of 'std::invalid_argument'\n  what():  stod\n",
      "parsed_errors": [

      ]
    },
    {
      "name": "3.x/for.chai",
      "status": "failed",
      "time": "0.474514",
      "output": "terminate called after throwing an instance of 'std::invalid_argument'\n  what():  stod\n",
      "parsed_errors": [

      ]
    },
    {
      "name": "3.x/generate_range.chai",
      "status": "failed",
      "time": "0.298267",
      "output": "terminate called after throwing an instance of 'std::invalid_argument'\n  what():  stod\n",
      "parsed_errors": [

      ]
    },
    {
      "name": "3.x/function_array_adjacent.chai",
      "status": "failed",
      "time": "0.304773",
      "output": "terminate called after throwing an instance of 'std::invalid_argument'\n  what():  stod\n",
      "parsed_errors": [

      ]
    },
    {
      "name": "3.x/function_introspection.chai",
      "status": "failed",
      "time": "0.318043",
      "output": "terminate called after throwing an instance of 'std::invalid_argument'\n  what():  stod\n",
      "parsed_errors": [

      ]
    },
    {
      "name": "3.x/function_reassignment.chai",
      "status": "failed",
      "time": "0.417402",
      "output": "terminate called after throwing an instance of 'std::invalid_argument'\n  what():  stod\n",
      "parsed_errors": [

      ]
    },
    {
      "name": "3.x/if.chai",
      "status": "failed",
      "time": "0.332655",
      "output": "terminate called after throwing an instance of 'std::invalid_argument'\n  what():  stod\n",
      "parsed_errors": [

      ]
    },
    {
      "name": "3.x/if_else.chai",
      "status": "failed",
      "time": "0.344188",
      "output": "terminate called after throwing an instance of 'std::invalid_argument'\n  what():  stod\n",
      "parsed_errors": [

      ]
    },
    {
      "name": "3.x/global_const_in_module.chai",
      "status": "failed",
      "time": "0.469642",
      "output": "terminate called after throwing an instance of 'std::invalid_argument'\n  what():  stod\n",
      "parsed_errors": [

      ]
    },
    {
      "name": "3.x/if_elseif_else.chai",
      "status": "failed",
      "time": "0.456835",
      "output": "terminate called after throwing an instance of 'std::invalid_argument'\n  what():  stod\n",
      "parsed_errors": [

      ]
    },
    {
      "name": "3.x/if_elseif.chai",
      "status": "failed",
      "time": "0.460798",
      "output": "terminate called after throwing an instance of 'std::invalid_argument'\n  what():  stod\n",
      "parsed_errors": [

      ]
    },
    {
      "name": "3.x/instring_eval.chai",
      "status": "failed",
      "time": "0.318171",
      "output": "terminate called after throwing an instance of 'std::invalid_argument'\n  what():  stod\n",
      "parsed_errors": [

      ]
    },
    {
      "name": "3.x/instring_eval_more.chai",
      "status": "failed",
      "time": "0.328614",
      "output": "terminate called after throwing an instance of 'std::invalid_argument'\n  what():  stod\n",
      "parsed_errors": [

      ]
    },
    {
      "name": "3.x/index_operator.chai",
      "status": "failed",
      "time": "0.54307",
      "output": "terminate called after throwing an instance of 'std::invalid_argument'\n  what():  stod\n",
      "parsed_errors": [

      ]
    },
    {
      "name": "3.x/inheritance.chai",
      "status": "failed",
      "time": "0.641284",
      "output": "terminate called after throwing an instance of 'std::invalid_argument'\n  what():  stod\n",
      "parsed_errors": [

      ]
    },
    {
      "name": "3.x/is_undef.chai",
      "status": "failed",
      "time": "0.315242",
      "output": "terminate called after throwing an instance of 'std::invalid_argument'\n  what():  stod\n",
      "parsed_errors": [

      ]
    },
    {
      "name": "3.x/join.chai",
      "status": "failed",
      "time": "0.428689",
      "output": "terminate called after throwing an instance of 'std::invalid_argument'\n  what():  stod\n",
      "parsed_errors": [

      ]
    },
    {
      "name": "3.x/invalid_function_reassignment.chai",
      "status": "failed",
      "time": "0.63902",
      "output": "terminate called after throwing an instance of 'std::invalid_argument'\n  what():  stod\n",
      "parsed_errors": [

      ]
    },
    {
      "name": "3.x/load_module.chai",
      "status": "failed",
      "time": "0.309297",
      "output": "terminate called after throwing an instance of 'std::invalid_argument'\n  what():  stod\n",
      "parsed_errors": [

      ]
    },
    {
      "name": "3.x/invalid_function_assignment.chai",
      "status": "failed",
      "time": "0.641405",
      "output": "terminate called after throwing an instance of 'std::invalid_argument'\n  what():  stod\n",
      "parsed_errors": [

      ]
    },
    {
      "name": "3.x/list_push_back.chai",
      "status": "failed",
      "time": "0.529431",
      "output": "terminate called after throwing an instance of 'std::invalid_argument'\n  what():  stod\n",
      "parsed_errors": [

      ]
    },
    {
      "name": "3.x/lambda.chai",
      "status": "failed",
      "time": "0.535825",
      "output": "terminate called after throwing an instance of 'std::invalid_argument'\n  what():  stod\n",
      "parsed_errors": [

      ]
    },
    {
      "name": "3.x/list_push_front.chai",
      "status": "failed",
      "time": "0.526803",
      "output": "terminate called after throwing an instance of 'std::invalid_argument'\n  what():  stod\n",
      "parsed_errors": [

      ]
    },
    {
      "name": "3.x/loop_inner_outer.chai",
      "status": "failed",
      "time": "0.309398",
      "output": "terminate called after throwing an instance of 'std::invalid_argument'\n  what():  stod\n",
      "parsed_errors": [

      ]
    },
    {
      "name": "3.x/map_access.chai",
      "status": "failed",
      "time": "0.303568",
      "output": "terminate called after throwing an instance of 'std::invalid_argument'\n  what():  stod\n",
      "parsed_errors": [

      ]
    },
    {
      "name": "3.x/map.chai",
      "status": "failed",
      "time": "0.330897",
      "output": "terminate called after throwing an instance of 'std::invalid_argument'\n  what():  stod\n",
      "parsed_errors": [

      ]
    },
    {
      "name": "3.x/malformed_inline_map.chai",
      "status": "failed",
      "time": "0.332114",
      "output": "terminate called after throwing an instance of 'std::invalid_argument'\n  what():  stod\n",
      "parsed_errors": [

      ]
    },
    {
      "name": "3.x/math_add_mixed.chai",
      "status": "failed",
      "time": "0.346966",
      "output": "terminate called after throwing an instance of 'std::invalid_argument'\n  what():  stod\n",
      "parsed_errors": [

      ]
    },
    {
      "name": "3.x/map_inplace_init.chai",
      "status": "failed",
      "time": "0.359132",
      "output": "terminate called after throwing an instance of 'std::invalid_argument'\n  what():  stod\n",
      "parsed_errors": [

      ]
    },
    {
      "name": "3.x/math_dec.chai",
      "status": "failed",
      "time": "0.359761",
      "output": "terminate called after throwing an instance of 'std::invalid_argument'\n  what():  stod\n",
      "parsed_errors": [

      ]
    },
    {
      "name": "3.x/math_add.chai",
      "status": "failed",
      "time": "0.374823",
      "output": "terminate called after throwing an instance of 'std::invalid_argument'\n  what():  stod\n",
      "parsed_errors": [

      ]
    },
    {
      "name": "3.x/math_div.chai",
      "status": "failed",
      "time": "0.359027",
      "output": "terminate called after throwing an instance of 'std::invalid_argument'\n  what():  stod\n",
      "parsed_errors": [

      ]
    },
    {
      "name": "3.x/math_mod.chai",
      "status": "failed",
      "time": "0.318463",
      "output": "terminate called after throwing an instance of 'std::invalid_argument'\n  what():  stod\n",
      "parsed_errors": [

      ]
    },
    {
      "name": "3.x/memberscope.chai",
      "status": "failed",
      "time": "0.305572",
      "output": "terminate called after throwing an instance of 'std::invalid_argument'\n  what():  stod\n",
      "parsed_errors": [

      ]
    },
    {
      "name": "3.x/math_negate.chai",
      "status": "failed",
      "time": "0.627513",
      "output": "terminate called after throwing an instance of 'std::invalid_argument'\n  what():  stod\n",
      "parsed_errors": [

      ]
    },
    {
      "name": "3.x/math_inc.chai",
      "status": "failed",
      "time": "0.636241",
      "output": "terminate called after throwing an instance of 'std::invalid_argument'\n  what():  stod\n",
      "parsed_errors": [

      ]
    },
    {
      "name": "3.x/math_mult.chai",
      "status": "failed",
      "time": "0.630018",
      "output": "terminate called after throwing an instance of 'std::invalid_argument'\n  what():  stod\n",
      "parsed_errors": [

      ]
    },
    {
      "name": "3.x/math_paren.chai",
      "status": "failed",
      "time": "0.313719",
      "output": "terminate called after throwing an instance of 'std::invalid_argument'\n  what():  stod\n",
      "parsed_errors": [

      ]
    },
    {
      "name": "3.x/math_sub.chai",
      "status": "failed",
      "time": "0.332199",
      "output": "terminate called after throwing an instance of 'std::invalid_argument'\n  what():  stod\n",
      "parsed_errors": [

      ]
    },
    {
      "name": "3.x/max.chai",
      "status": "failed",
      "time": "0.330535",
      "output": "terminate called after throwing an instance of 'std::invalid_argument'\n  what():  stod\n",
      "parsed_errors": [

      ]
    },
    {
      "name": "3.x/mmd1.chai",
      "status": "failed",
      "time": "0.349254",
      "output": "terminate called after throwing an instance of 'std::invalid_argument'\n  what():  stod\n",
      "parsed_errors": [

      ]
    },
    {
      "name": "3.x/mmd2.chai",
      "status": "failed",
      "time": "0.35573",
      "output": "terminate called after throwing an instance of 'std::invalid_argument'\n  what():  stod\n",
      "parsed_errors": [

      ]
    },
    {
      "name": "3.x/min.chai",
      "status": "failed",
      "time": "0.373333",
      "output": "terminate called after throwing an instance of 'std::invalid_argument'\n  what():  stod\n",
      "parsed_errors": [

      ]
    },
    {
      "name": "3.x/method_sugar.chai",
      "status": "failed",
      "time": "0.377799",
      "output": "terminate called after throwing an instance of 'std::invalid_argument'\n  what():  stod\n",
      "parsed_errors": [

      ]
    },
    {
      "name": "3.x/multiline.chai",
      "status": "failed",
      "time": "0.365734",
      "output": "terminate called after throwing an instance of 'std::invalid_argument'\n  what():  stod\n",
      "parsed_errors": [

      ]
    },
    {
      "name": "3.x/number_formats.chai",
      "status": "failed",
      "time": "0.315997",
      "output": "terminate called after throwing an instance of 'std::invalid_argument'\n  what():  stod\n",
      "parsed_errors": [

      ]
    },
    {
      "name": "3.x/object_attr.chai",
      "status": "failed",
      "time": "0.630339",
      "output": "terminate called after throwing an instance of 'std::invalid_argument'\n  what():  stod\n",
      "parsed_errors": [

      ]
    },
    {
      "name": "3.x/object_constructor_guards.chai",
      "status": "failed",
      "time": "0.318011",
      "output": "terminate called after throwing an instance of 'std::invalid_argument'\n  what():  stod\n",
      "parsed_errors": [

      ]
    },
    {
      "name": "3.x/object_clone.chai",
      "status": "failed",
      "time": "0.626447",
      "output": "terminate called after throwing an instance of 'std::invalid_argument'\n  what():  stod\n",
      "parsed_errors": [

      ]
    },
    {
      "name": "3.x/object_attr_same_name.chai",
      "status": "failed",
      "time": "0.630853",
      "output": "terminate called after throwing an instance of 'std::invalid_argument'\n  what():  stod\n",
      "parsed_errors": [

      ]
    },
    {
      "name": "3.x/odd.chai",
      "status": "failed",
      "time": "0.326552",
      "output": "terminate called after throwing an instance of 'std::invalid_argument'\n  what():  stod\n",
      "parsed_errors": [

      ]
    },
    {
      "name": "3.x/object_method_guards.chai",
      "status": "failed",
      "time": "0.428815",
      "output": "terminate called after throwing an instance of 'std::invalid_argument'\n  what():  stod\n",
      "parsed_errors": [

      ]
    },
    {
      "name": "3.x/operator_overload.chai",
      "status": "failed",
      "time": "0.523616",
      "output": "terminate called after throwing an instance of 'std::invalid_argument'\n  what():  stod\n",
      "parsed_errors": [

      ]
    },
    {
      "name": "3.x/operator_overload2.chai",
      "status": "failed",
      "time": "0.315137",
      "output": "terminate called after throwing an instance of 'std::invalid_argument'\n  what():  stod\n",
      "parsed_errors": [

      ]
    },
    {
      "name": "3.x/operators_int.chai",
      "status": "failed",
      "time": "0.425241",
      "output": "terminate called after throwing an instance of 'std::invalid_argument'\n  what():  stod\n",
      "parsed_errors": [

      ]
    },
    {
      "name": "3.x/operators_float.chai",
      "status": "failed",
      "time": "0.429675",
      "output": "terminate called after throwing an instance of 'std::invalid_argument'\n  what():  stod\n",
      "parsed_errors": [

      ]
    },
    {
      "name": "3.x/pointer_passed_to_constructor.chai",
      "status": "failed",
      "time": "0.304687",
      "output": "terminate called after throwing an instance of 'std::invalid_argument'\n  what():  stod\n",
      "parsed_errors": [

      ]
    },
    {
      "name": "3.x/precedence_1.chai",
      "status": "failed",
      "time": "0.317139",
      "output": "terminate called after throwing an instance of 'std::invalid_argument'\n  what():  stod\n",
      "parsed_errors": [

      ]
    },
    {
      "name": "3.x/pair.chai",
      "status": "failed",
      "time": "0.62627",
      "output": "terminate called after throwing an instance of 'std::invalid_argument'\n  what():  stod\n",
      "parsed_errors": [

      ]
    },
    {
      "name": "3.x/precedence_2.chai",
      "status": "failed",
      "time": "0.33007",
      "output": "terminate called after throwing an instance of 'std::invalid_argument'\n  what():  stod\n",
      "parsed_errors": [

      ]
    },
    {
      "name": "3.x/precedence_3.chai",
      "status": "failed",
      "time": "0.630794",
      "output": "terminate called after throwing an instance of 'std::invalid_argument'\n  what():  stod\n",
      "parsed_errors": [

      ]
    },
    {
      "name": "3.x/product.chai",
      "status": "failed",
      "time": "0.34552",
      "output": "terminate called after throwing an instance of 'std::invalid_argument'\n  what():  stod\n",
      "parsed_errors": [

      ]
    },
    {
      "name": "3.x/range_back.chai",
      "status": "failed",
      "time": "0.33924",
      "output": "terminate called after throwing an instance of 'std::invalid_argument'\n  what():  stod\n",
      "parsed_errors": [

      ]
    },
    {
      "name": "3.x/range_contains.chai",
      "status": "failed",
      "time": "0.464138",
      "output": "terminate called after throwing an instance of 'std::invalid_argument'\n  what():  stod\n",
      "parsed_errors": [

      ]
    },
    {
      "name": "3.x/precedence_eq.chai",
      "status": "failed",
      "time": "0.475552",
      "output": "terminate called after throwing an instance of 'std::invalid_argument'\n  what():  stod\n",
      "parsed_errors": [

      ]
    },
    {
      "name": "3.x/range.chai",
      "status": "failed",
      "time": "0.471825",
      "output": "terminate called after throwing an instance of 'std::invalid_argument'\n  what():  stod\n",
      "parsed_errors": [

      ]
    },
    {
      "name": "3.x/range_find.chai",
      "status": "failed",
      "time": "0.314561",
      "output": "terminate called after throwing an instance of 'std::invalid_argument'\n  what():  stod\n",
      "parsed_errors": [

      ]
    },
    {
      "name": "3.x/ref_equal.chai",
      "status": "failed",
      "time": "0.313245",
      "output": "terminate called after throwing an instance of 'std::invalid_argument'\n  what():  stod\n",
      "parsed_errors": [

      ]
    },
    {
      "name": "3.x/range_inplace.chai",
      "status": "failed",
      "time": "0.340217",
      "output": "terminate called after throwing an instance of 'std::invalid_argument'\n  what():  stod\n",
      "parsed_errors": [

      ]
    },
    {
      "name": "3.x/reduce.chai",
      "status": "failed",
      "time": "0.649779",
      "output": "terminate called after throwing an instance of 'std::invalid_argument'\n  what():  stod\n",
      "parsed_errors": [

      ]
    },
    {
      "name": "3.x/retro.chai",
      "status": "failed",
      "time": "0.362327",
      "output": "terminate called after throwing an instance of 'std::invalid_argument'\n  what():  stod\n",
      "parsed_errors": [

      ]
    },
    {
      "name": "3.x/retroretro.chai",
      "status": "failed",
      "time": "0.35876",
      "output": "terminate called after throwing an instance of 'std::invalid_argument'\n  what():  stod\n",
      "parsed_errors": [

      ]
    },
    {
      "name": "3.x/runtime_error.chai",
      "status": "failed",
      "time": "0.467451",
      "output": "terminate called after throwing an instance of 'std::invalid_argument'\n  what():  stod\n",
      "parsed_errors": [

      ]
    },
    {
      "name": "3.x/return.chai",
      "status": "failed",
      "time": "0.569886",
      "output": "terminate called after throwing an instance of 'std::invalid_argument'\n  what():  stod\n",
      "parsed_errors": [

      ]
    },
    {
      "name": "3.x/string_charptr.chai",
      "status": "failed",
      "time": "0.295242",
      "output": "terminate called after throwing an instance of 'std::invalid_argument'\n  what():  stod\n",
      "parsed_errors": [

      ]
    },
    {
      "name": "3.x/reflection_test.chai",
      "status": "failed",
      "time": "0.663401",
      "output": "terminate called after throwing an instance of 'std::invalid_argument'\n  what():  stod\n",
      "parsed_errors": [

      ]
    },
    {
      "name": "3.x/shift.chai",
      "status": "failed",
      "time": "0.299938",
      "output": "terminate called after throwing an instance of 'std::invalid_argument'\n  what():  stod\n",
      "parsed_errors": [

      ]
    },
    {
      "name": "3.x/string_concat.chai",
      "status": "failed",
      "time": "0.333067",
      "output": "terminate called after throwing an instance of 'std::invalid_argument'\n  what():  stod\n",
      "parsed_errors": [

      ]
    },
    {
      "name": "3.x/string_find.chai",
      "status": "failed",
      "time": "0.330466",
      "output": "terminate called after throwing an instance of 'std::invalid_argument'\n  what():  stod\n",
      "parsed_errors": [

      ]
    },
    {
      "name": "3.x/string_find_first_of.chai",
      "status": "failed",
      "time": "0.337874",
      "output": "terminate called after throwing an instance of 'std::invalid_argument'\n  what():  stod\n",
      "parsed_errors": [

      ]
    },
    {
      "name": "3.x/string_find_last_of.chai",
      "status": "failed",
      "time": "0.350781",
      "output": "terminate called after throwing an instance of 'std::invalid_argument'\n  what():  stod\n",
      "parsed_errors": [

      ]
    },
    {
      "name": "3.x/string_find_last_not_of.chai",
      "status": "failed",
      "time": "0.470413",
      "output": "terminate called after throwing an instance of 'std::invalid_argument'\n  what():  stod\n",
      "parsed_errors": [

      ]
    },
    {
      "name": "3.x/string_init.chai",
      "status": "failed",
      "time": "0.460652",
      "output": "terminate called after throwing an instance of 'std::invalid_argument'\n  what():  stod\n",
      "parsed_errors": [

      ]
    },
    {
      "name": "3.x/string_find_first_not_of.chai",
      "status": "failed",
      "time": "0.576785",
      "output": "terminate called after throwing an instance of 'std::invalid_argument'\n  what():  stod\n",
      "parsed_errors": [

      ]
    },
    {
      "name": "3.x/string_literal_access.chai",
      "status": "failed",
      "time": "0.317797",
      "output": "terminate called after throwing an instance of 'std::invalid_argument'\n  what():  stod\n",
      "parsed_errors": [

      ]
    },
    {
      "name": "3.x/sum.chai",
      "status": "failed",
      "time": "0.323192",
      "output": "terminate called after throwing an instance of 'std::invalid_argument'\n  what():  stod\n",
      "parsed_errors": [

      ]
    },
    {
      "name": "3.x/string_rfind.chai",
      "status": "failed",
      "time": "0.53493",
      "output": "terminate called after throwing an instance of 'std::invalid_argument'\n  what():  stod\n",
      "parsed_errors": [

      ]
    },
    {
      "name": "3.x/switch_break.chai",
      "status": "failed",
      "time": "0.629687",
      "output": "terminate called after throwing an instance of 'std::invalid_argument'\n  what():  stod\n",
      "parsed_errors": [

      ]
    },
    {
      "name": "3.x/switch_default.chai",
      "status": "failed",
      "time": "0.320641",
      "output": "terminate called after throwing an instance of 'std::invalid_argument'\n  what():  stod\n",
      "parsed_errors": [

      ]
    },
    {
      "name": "3.x/switch_empty.chai",
      "status": "failed",
      "time": "0.339769",
      "output": "terminate called after throwing an instance of 'std::invalid_argument'\n  what():  stod\n",
      "parsed_errors": [

      ]
    },
    {
      "name": "3.x/switch_fallthru.chai",
      "status": "failed",
      "time": "0.338359",
      "output": "terminate called after throwing an instance of 'std::invalid_argument'\n  what():  stod\n",
      "parsed_errors": [

      ]
    },
    {
      "name": "3.x/switch_fallthru_and_break.chai",
      "status": "failed",
      "time": "0.436788",
      "output": "terminate called after throwing an instance of 'std::invalid_argument'\n  what():  stod\n",
      "parsed_errors": [

      ]
    },
    {
      "name": "3.x/take.chai",
      "status": "failed",
      "time": "0.297719",
      "output": "terminate called after throwing an instance of 'std::invalid_argument'\n  what():  stod\n",
      "parsed_errors": [

      ]
    },
    {
      "name": "3.x/use.chai",
      "status": "failed",
      "time": "0.299667",
      "output": "terminate called after throwing an instance of 'std::invalid_argument'\n  what():  stod\n",
      "parsed_errors": [

      ]
    },
    {
      "name": "3.x/take_while.chai",
      "status": "failed",
      "time": "0.634121",
      "output": "terminate called after throwing an instance of 'std::invalid_argument'\n  what():  stod\n",
      "parsed_errors": [

      ]
    },
    {
      "name": "3.x/vector_insert_at.chai",
      "status": "failed",
      "time": "0.347156",
      "output": "terminate called after throwing an instance of 'std::invalid_argument'\n  what():  stod\n",
      "parsed_errors": [

      ]
    },
    {
      "name": "3.x/type_info.chai",
      "status": "failed",
      "time": "0.660462",
      "output": "terminate called after throwing an instance of 'std::invalid_argument'\n  what():  stod\n",
      "parsed_errors": [

      ]
    },
    {
      "name": "3.x/vector_literal_acccess.chai",
      "status": "failed",
      "time": "0.347012",
      "output": "terminate called after throwing an instance of 'std::invalid_argument'\n  what():  stod\n",
      "parsed_errors": [

      ]
    },
    {
      "name": "3.x/vector_access.chai",
      "status": "failed",
      "time": "0.386127",
      "output": "terminate called after throwing an instance of 'std::invalid_argument'\n  what():  stod\n",
      "parsed_errors": [

      ]
    },
    {
      "name": "3.x/vector_erase_at.chai",
      "status": "failed",
      "time": "0.383023",
      "output": "terminate called after throwing an instance of 'std::invalid_argument'\n  what():  stod\n",
      "parsed_errors": [

      ]
    },
    {
      "name": "3.x/vector_inplace_init.chai",
      "status": "failed",
      "time": "0.378363",
      "output": "terminate called after throwing an instance of 'std::invalid_argument'\n  what():  stod\n",
      "parsed_errors": [

      ]
    },
    {
      "name": "3.x/vector_push_empty.chai",
      "status": "failed",
      "time": "0.308944",
      "output": "terminate called after throwing an instance of 'std::invalid_argument'\n  what():  stod\n",
      "parsed_errors": [

      ]
    },
    {
      "name": "3.x/vector_of_one.chai",
      "status": "failed",
      "time": "0.321294",
      "output": "terminate called after throwing an instance of 'std::invalid_argument'\n  what():  stod\n",
      "parsed_errors": [

      ]
    },
    {
      "name": "3.x/vector_paren_literal_access.chai",
      "status": "failed",
      "time": "0.642333",
      "output": "terminate called after throwing an instance of 'std::invalid_argument'\n  what():  stod\n",
      "parsed_errors": [

      ]
    },
    {
      "name": "3.x/vector_push_back.chai",
      "status": "failed",
      "time": "0.634098",
      "output": "terminate called after throwing an instance of 'std::invalid_argument'\n  what():  stod\n",
      "parsed_errors": [

      ]
    },
    {
      "name": "array_types.chai",
      "status": "failed",
      "time": "0.343363",
      "output": "terminate called after throwing an instance of 'std::invalid_argument'\n  what():  stod\n",
      "parsed_errors": [

      ]
    },
    {
      "name": "assign_const.chai",
      "status": "failed",
      "time": "0.341509",
      "output": "terminate called after throwing an instance of 'std::invalid_argument'\n  what():  stod\n",
      "parsed_errors": [

      ]
    },
    {
      "name": "bind.chai",
      "status": "failed",
      "time": "0.344796",
      "output": "terminate called after throwing an instance of 'std::invalid_argument'\n  what():  stod\n",
      "parsed_errors": [

      ]
    },
    {
      "name": "3.x/zip.chai",
      "status": "failed",
      "time": "0.361179",
      "output": "terminate called after throwing an instance of 'std::invalid_argument'\n  what():  stod\n",
      "parsed_errors": [

      ]
    },
    {
      "name": "3.x/zip_with.chai",
      "status": "failed",
      "time": "0.359038",
      "output": "terminate called after throwing an instance of 'std::invalid_argument'\n  what():  stod\n",
      "parsed_errors": [

      ]
    },
    {
      "name": "bool_not.chai",
      "status": "failed",
      "time": "0.308249",
      "output": "terminate called after throwing an instance of 'std::invalid_argument'\n  what():  stod\n",
      "parsed_errors": [

      ]
    },
    {
      "name": "break_for.chai",
      "status": "failed",
      "time": "0.306596",
      "output": "terminate called after throwing an instance of 'std::invalid_argument'\n  what():  stod\n",
      "parsed_errors": [

      ]
    },
    {
      "name": "bind2.chai",
      "status": "failed",
      "time": "0.639041",
      "output": "terminate called after throwing an instance of 'std::invalid_argument'\n  what():  stod\n",
      "parsed_errors": [

      ]
    },
    {
      "name": "block_start.chai",
      "status": "failed",
      "time": "0.634572",
      "output": "terminate called after throwing an instance of 'std::invalid_argument'\n  what():  stod\n",
      "parsed_errors": [

      ]
    },
    {
      "name": "class.chai",
      "status": "failed",
      "time": "0.336759",
      "output": "terminate called after throwing an instance of 'std::invalid_argument'\n  what():  stod\n",
      "parsed_errors": [

      ]
    },
    {
      "name": "classification.chai",
      "status": "failed",
      "time": "0.346912",
      "output": "terminate called after throwing an instance of 'std::invalid_argument'\n  what():  stod\n",
      "parsed_errors": [

      ]
    },
    {
      "name": "collate.chai",
      "status": "failed",
      "time": "0.359834",
      "output": "terminate called after throwing an instance of 'std::invalid_argument'\n  what():  stod\n",
      "parsed_errors": [

      ]
    },
    {
      "name": "break_while.chai",
      "status": "failed",
      "time": "0.37423",
      "output": "terminate called after throwing an instance of 'std::invalid_argument'\n  what():  stod\n",
      "parsed_errors": [

      ]
    },
    {
      "name": "char_init.chai",
      "status": "failed",
      "time": "0.37039",
      "output": "terminate called after throwing an instance of 'std::invalid_argument'\n  what():  stod\n",
      "parsed_errors": [

      ]
    },
    {
      "name": "concat.chai",
      "status": "failed",
      "time": "0.30535",
      "output": "terminate called after throwing an instance of 'std::invalid_argument'\n  what():  stod\n",
      "parsed_errors": [

      ]
    },
    {
      "name": "const_range_test.chai",
      "status": "failed",
      "time": "0.329907",
      "output": "terminate called after throwing an instance of 'std::invalid_argument'\n  what():  stod\n",
      "parsed_errors": [

      ]
    },
    {
      "name": "compare_gt.chai",
      "status": "failed",
      "time": "0.625848",
      "output": "terminate called after throwing an instance of 'std::invalid_argument'\n  what():  stod\n",
      "parsed_errors": [

      ]
    },
    {
      "name": "compare_lt.chai",
      "status": "failed",
      "time": "0.623765",
      "output": "terminate called after throwing an instance of 'std::invalid_argument'\n  what():  stod\n",
      "parsed_errors": [

      ]
    },
    {
      "name": "convert_int_string.chai",
      "status": "failed",
      "time": "0.404825",
      "output": "terminate called after throwing an instance of 'std::invalid_argument'\n  what():  stod\n",
      "parsed_errors": [

      ]
    },
    {
      "name": "convert_string_double.chai",
      "status": "failed",
      "time": "0.408235",
      "output": "terminate called after throwing an instance of 'std::invalid_argument'\n  what():  stod\n",
      "parsed_errors": [

      ]
    },
    {
      "name": "continue_for.chai",
      "status": "failed",
      "time": "0.534362",
      "output": "terminate called after throwing an instance of 'std::invalid_argument'\n  what():  stod\n",
      "parsed_errors": [

      ]
    },
    {
      "name": "continue_while.chai",
      "status": "failed",
      "time": "0.532372",
      "output": "terminate called after throwing an instance of 'std::invalid_argument'\n  what():  stod\n",
      "parsed_errors": [

      ]
    },
    {
      "name": "dispatch_functions.chai",
      "status": "failed",
      "time": "0.307944",
      "output": "terminate called after throwing an instance of 'std::invalid_argument'\n  what():  stod\n",
      "parsed_errors": [

      ]
    },
    {
      "name": "convert_double_string.chai",
      "status": "failed",
      "time": "0.729234",
      "output": "terminate called after throwing an instance of 'std::invalid_argument'\n  what():  stod\n",
      "parsed_errors": [

      ]
    },
    {
      "name": "divide_by_zero_protection.chai",
      "status": "failed",
      "time": "0.304859",
      "output": "terminate called after throwing an instance of 'std::invalid_argument'\n  what():  stod\n",
      "parsed_errors": [

      ]
    },
    {
      "name": "convert_string_int.chai",
      "status": "failed",
      "time": "0.340769",
      "output": "terminate called after throwing an instance of 'std::invalid_argument'\n  what():  stod\n",
      "parsed_errors": [

      ]
    },
    {
      "name": "deep_array_lookup.chai",
      "status": "failed",
      "time": "0.543239",
      "output": "terminate called after throwing an instance of 'std::invalid_argument'\n  what():  stod\n",
      "parsed_errors": [

      ]
    },
    {
      "name": "empty.chai",
      "status": "failed",
      "time": "0.348842",
      "output": "terminate called after throwing an instance of 'std::invalid_argument'\n  what():  stod\n",
      "parsed_errors": [

      ]
    },
    {
      "name": "equ_shortform.chai",
      "status": "failed",
      "time": "0.339963",
      "output": "terminate called after throwing an instance of 'std::invalid_argument'\n  what():  stod\n",
      "parsed_errors": [

      ]
    },
    {
      "name": "drop.chai",
      "status": "failed",
      "time": "0.473178",
      "output": "terminate called after throwing an instance of 'std::invalid_argument'\n  what():  stod\n",
      "parsed_errors": [

      ]
    },
    {
      "name": "drop_while.chai",
      "status": "failed",
      "time": "0.471476",
      "output": "terminate called after throwing an instance of 'std::invalid_argument'\n  what():  stod\n",
      "parsed_errors": [

      ]
    },
    {
      "name": "dynamic_object_dynamic_attrs.chai",
      "status": "failed",
      "time": "0.566565",
      "output": "terminate called after throwing an instance of 'std::invalid_argument'\n  what():  stod\n",
      "parsed_errors": [

      ]
    },
    {
      "name": "even.chai",
      "status": "failed",
      "time": "0.311303",
      "output": "terminate called after throwing an instance of 'std::invalid_argument'\n  what():  stod\n",
      "parsed_errors": [

      ]
    },
    {
      "name": "eval.chai",
      "status": "failed",
      "time": "0.337031",
      "output": "terminate called after throwing an instance of 'std::invalid_argument'\n  what():  stod\n",
      "parsed_errors": [

      ]
    },
    {
      "name": "eval_error.chai",
      "status": "failed",
      "time": "0.53649",
      "output": "terminate called after throwing an instance of 'std::invalid_argument'\n  what():  stod\n",
      "parsed_errors": [

      ]
    },
    {
      "name": "exception_guards.chai",
      "status": "failed",
      "time": "0.309152",
      "output": "terminate called after throwing an instance of 'std::invalid_argument'\n  what():  stod\n",
      "parsed_errors": [

      ]
    },
    {
      "name": "eval_file.chai",
      "status": "failed",
      "time": "0.627343",
      "output": "terminate called after throwing an instance of 'std::invalid_argument'\n  what():  stod\n",
      "parsed_errors": [

      ]
    },
    {
      "name": "exception_typed.chai",
      "status": "failed",
      "time": "0.311672",
      "output": "terminate called after throwing an instance of 'std::invalid_argument'\n  what():  stod\n",
      "parsed_errors": [

      ]
    },
    {
      "name": "exception.chai",
      "status": "failed",
      "time": "0.437093",
      "output": "terminate called after throwing an instance of 'std::invalid_argument'\n  what():  stod\n",
      "parsed_errors": [

      ]
    },
    {
      "name": "exception_finally.chai",
      "status": "failed",
      "time": "0.435204",
      "output": "terminate called after throwing an instance of 'std::invalid_argument'\n  what():  stod\n",
      "parsed_errors": [

      ]
    },
    {
      "name": "float.chai",
      "status": "failed",
      "time": "0.350886",
      "output": "terminate called after throwing an instance of 'std::invalid_argument'\n  what():  stod\n",
      "parsed_errors": [

      ]
    },
    {
      "name": "foldl.chai",
      "status": "failed",
      "time": "0.349465",
      "output": "terminate called after throwing an instance of 'std::invalid_argument'\n  what():  stod\n",
      "parsed_errors": [

      ]
    },
    {
      "name": "for.chai",
      "status": "failed",
      "time": "0.359827",
      "output": "terminate called after throwing an instance of 'std::invalid_argument'\n  what():  stod\n",
      "parsed_errors": [

      ]
    },
    {
      "name": "exception_typed_2.chai",
      "status": "failed",
      "time": "0.571845",
      "output": "terminate called after throwing an instance of 'std::invalid_argument'\n  what():  stod\n",
      "parsed_errors": [

      ]
    },
    {
      "name": "filter.chai",
      "status": "failed",
      "time": "0.569036",
      "output": "terminate called after throwing an instance of 'std::invalid_argument'\n  what():  stod\n",
      "parsed_errors": [

      ]
    },
    {
      "name": "function_array_adjacent.chai",
      "status": "failed",
      "time": "0.323204",
      "output": "terminate called after throwing an instance of 'std::invalid_argument'\n  what():  stod\n",
      "parsed_errors": [

      ]
    },
    {
      "name": "for_each.chai",
      "status": "failed",
      "time": "0.346025",
      "output": "terminate called after throwing an instance of 'std::invalid_argument'\n  what():  stod\n",
      "parsed_errors": [

      ]
    },
    {
      "name": "for_each_range.chai",
      "status": "failed",
      "time": "0.340883",
      "output": "terminate called after throwing an instance of 'std::invalid_argument'\n  what():  stod\n",
      "parsed_errors": [

      ]
    },
    {
      "name": "for_each_retro.chai",
      "status": "failed",
      "time": "0.540933",
      "output": "terminate called after throwing an instance of 'std::invalid_argument'\n  what():  stod\n",
      "parsed_errors": [

      ]
    },
    {
      "name": "function_reassignment.chai",
      "status": "failed",
      "time": "0.310813",
      "output": "terminate called after throwing an instance of 'std::invalid_argument'\n  what():  stod\n",
      "parsed_errors": [

      ]
    },
    {
      "name": "function_attributes.chai",
      "status": "failed",
      "time": "0.535942",
      "output": "terminate called after throwing an instance of 'std::invalid_argument'\n  what():  stod\n",
      "parsed_errors": [

      ]
    },
    {
      "name": "function_introspection.chai",
      "status": "failed",
      "time": "0.53207",
      "output": "terminate called after throwing an instance of 'std::invalid_argument'\n  what():  stod\n",
      "parsed_errors": [

      ]
    },
    {
      "name": "generate_range.chai",
      "status": "failed",
      "time": "0.306483",
      "output": "terminate called after throwing an instance of 'std::invalid_argument'\n  what():  stod\n",
      "parsed_errors": [

      ]
    },
    {
      "name": "function_members.chai",
      "status": "failed",
      "time": "0.626547",
      "output": "terminate called after throwing an instance of 'std::invalid_argument'\n  what():  stod\n",
      "parsed_errors": [

      ]
    },
    {
      "name": "global_const_in_module.chai",
      "status": "failed",
      "time": "0.304888",
      "output": "terminate called after throwing an instance of 'std::invalid_argument'\n  what():  stod\n",
      "parsed_errors": [

      ]
    },
    {
      "name": "function_redefinition.chai",
      "status": "failed",
      "time": "0.331546",
      "output": "terminate called after throwing an instance of 'std::invalid_argument'\n  what():  stod\n",
      "parsed_errors": [

      ]
    },
    {
      "name": "future.chai",
      "status": "failed",
      "time": "0.328872",
      "output": "terminate called after throwing an instance of 'std::invalid_argument'\n  what():  stod\n",
      "parsed_errors": [

      ]
    },
    {
      "name": "if_else.chai",
      "status": "failed",
      "time": "0.345598",
      "output": "terminate called after throwing an instance of 'std::invalid_argument'\n  what():  stod\n",
      "parsed_errors": [

      ]
    },
    {
      "name": "if_elseif.chai",
      "status": "failed",
      "time": "0.34292",
      "output": "terminate called after throwing an instance of 'std::invalid_argument'\n  what():  stod\n",
      "parsed_errors": [

      ]
    },
    {
      "name": "global_in_script.chai",
      "status": "failed",
      "time": "0.585202",
      "output": "terminate called after throwing an instance of 'std::invalid_argument'\n  what():  stod\n",
      "parsed_errors": [

      ]
    },
    {
      "name": "hashbang.chai",
      "status": "failed",
      "time": "0.583166",
      "output": "terminate called after throwing an instance of 'std::invalid_argument'\n  what():  stod\n",
      "parsed_errors": [

      ]
    },
    {
      "name": "if.chai",
      "status": "failed",
      "time": "0.579538",
      "output": "terminate called after throwing an instance of 'std::invalid_argument'\n  what():  stod\n",
      "parsed_errors": [

      ]
    },
    {
      "name": "instring_eval.chai",
      "status": "failed",
      "time": "0.386908",
      "output": "terminate called after throwing an instance of 'std::invalid_argument'\n  what():  stod\n",
      "parsed_errors": [

      ]
    },
    {
      "name": "if_elseif_else.chai",
      "status": "failed",
      "time": "0.452886",
      "output": "terminate called after throwing an instance of 'std::invalid_argument'\n  what():  stod\n",
      "parsed_errors": [

      ]
    },
    {
      "name": "index_operator.chai",
      "status": "failed",
      "time": "0.450235",
      "output": "terminate called after throwing an instance of 'std::invalid_argument'\n  what():  stod\n",
      "parsed_errors": [

      ]
    },
    {
      "name": "invalid_function_reassignment.chai",
      "status": "failed",
      "time": "0.339133",
      "output": "terminate called after throwing an instance of 'std::invalid_argument'\n  what():  stod\n",
      "parsed_errors": [

      ]
    },
    {
      "name": "inheritance.chai",
      "status": "failed",
      "time": "0.754725",
      "output": "terminate called after throwing an instance of 'std::invalid_argument'\n  what():  stod\n",
      "parsed_errors": [

      ]
    },
    {
      "name": "is_undef.chai",
      "status": "failed",
      "time": "0.322151",
      "output": "terminate called after throwing an instance of 'std::invalid_argument'\n  what():  stod\n",
      "parsed_errors": [

      ]
    },
    {
      "name": "instring_eval_more.chai",
      "status": "failed",
      "time": "0.587551",
      "output": "terminate called after throwing an instance of 'std::invalid_argument'\n  what():  stod\n",
      "parsed_errors": [

      ]
    },
    {
      "name": "invalid_function_assignment.chai",
      "status": "failed",
      "time": "0.570143",
      "output": "terminate called after throwing an instance of 'std::invalid_argument'\n  what():  stod\n",
      "parsed_errors": [

      ]
    },
    {
      "name": "list_push_front.chai",
      "status": "failed",
      "time": "0.37152",
      "output": "terminate called after throwing an instance of 'std::invalid_argument'\n  what():  stod\n",
      "parsed_errors": [

      ]
    },
    {
      "name": "load_module.chai",
      "status": "failed",
      "time": "0.374531",
      "output": "terminate called after throwing an instance of 'std::invalid_argument'\n  what():  stod\n",
      "parsed_errors": [

      ]
    },
    {
      "name": "join.chai",
      "status": "failed",
      "time": "0.407249",
      "output": "terminate called after throwing an instance of 'std::invalid_argument'\n  what():  stod\n",
      "parsed_errors": [

      ]
    },
    {
      "name": "lambda.chai",
      "status": "failed",
      "time": "0.405277",
      "output": "terminate called after throwing an instance of 'std::invalid_argument'\n  what():  stod\n",
      "parsed_errors": [

      ]
    },
    {
      "name": "list_push_back.chai",
      "status": "failed",
      "time": "0.603572",
      "output": "terminate called after throwing an instance of 'std::invalid_argument'\n  what():  stod\n",
      "parsed_errors": [

      ]
    },
    {
      "name": "malformed_inline_map.chai",
      "status": "failed",
      "time": "0.313345",
      "output": "terminate called after throwing an instance of 'std::invalid_argument'\n  what():  stod\n",
      "parsed_errors": [

      ]
    },
    {
      "name": "map.chai",
      "status": "failed",
      "time": "0.305112",
      "output": "terminate called after throwing an instance of 'std::invalid_argument'\n  what():  stod\n",
      "parsed_errors": [

      ]
    },
    {
      "name": "logical_short_circuiting.chai",
      "status": "failed",
      "time": "0.537918",
      "output": "terminate called after throwing an instance of 'std::invalid_argument'\n  what():  stod\n",
      "parsed_errors": [

      ]
    },
    {
      "name": "loop_inner_outer.chai",
      "status": "failed",
      "time": "0.535404",
      "output": "terminate called after throwing an instance of 'std::invalid_argument'\n  what():  stod\n",
      "parsed_errors": [

      ]
    },
    {
      "name": "math_add.chai",
      "status": "failed",
      "time": "0.345801",
      "output": "terminate called after throwing an instance of 'std::invalid_argument'\n  what():  stod\n",
      "parsed_errors": [

      ]
    },
    {
      "name": "math_add_mixed.chai",
      "status": "failed",
      "time": "0.341848",
      "output": "terminate called after throwing an instance of 'std::invalid_argument'\n  what():  stod\n",
      "parsed_errors": [

      ]
    },
    {
      "name": "map_access.chai",
      "status": "failed",
      "time": "0.366241",
      "output": "terminate called after throwing an instance of 'std::invalid_argument'\n  what():  stod\n",
      "parsed_errors": [

      ]
    },
    {
      "name": "map_count.chai",
      "status": "failed",
      "time": "0.363863",
      "output": "terminate called after throwing an instance of 'std::invalid_argument'\n  what():  stod\n",
      "parsed_errors": [

      ]
    },
    {
      "name": "map_inplace_init.chai",
      "status": "failed",
      "time": "0.567242",
      "output": "terminate called after throwing an instance of 'std::invalid_argument'\n  what():  stod\n",
      "parsed_errors": [

      ]
    },
    {
      "name": "math_inc.chai",
      "status": "failed",
      "time": "0.301661",
      "output": "terminate called after throwing an instance of 'std::invalid_argument'\n  what():  stod\n",
      "parsed_errors": [

      ]
    },
    {
      "name": "math_mod.chai",
      "status": "failed",
      "time": "0.305337",
      "output": "terminate called after throwing an instance of 'std::invalid_argument'\n  what():  stod\n",
      "parsed_errors": [

      ]
    },
    {
      "name": "math_dec.chai",
      "status": "failed",
      "time": "0.537777",
      "output": "terminate called after throwing an instance of 'std::invalid_argument'\n  what():  stod\n",
      "parsed_errors": [

      ]
    },
    {
      "name": "math_div.chai",
      "status": "failed",
      "time": "0.533817",
      "output": "terminate called after throwing an instance of 'std::invalid_argument'\n  what():  stod\n",
      "parsed_errors": [

      ]
    },
    {
      "name": "math_sub.chai",
      "status": "failed",
      "time": "0.333989",
      "output": "terminate called after throwing an instance of 'std::invalid_argument'\n  what():  stod\n",
      "parsed_errors": [

      ]
    },
    {
      "name": "max.chai",
      "status": "failed",
      "time": "0.351021",
      "output": "terminate called after throwing an instance of 'std::invalid_argument'\n  what():  stod\n",
      "parsed_errors": [

      ]
    },
    {
      "name": "math_mult.chai",
      "status": "failed",
      "time": "0.378543",
      "output": "terminate called after throwing an instance of 'std::invalid_argument'\n  what():  stod\n",
      "parsed_errors": [

      ]
    },
    {
      "name": "math_negate.chai",
      "status": "failed",
      "time": "0.374695",
      "output": "terminate called after throwing an instance of 'std::invalid_argument'\n  what():  stod\n",
      "parsed_errors": [

      ]
    },
    {
      "name": "math_paren.chai",
      "status": "failed",
      "time": "0.573888",
      "output": "terminate called after throwing an instance of 'std::invalid_argument'\n  what():  stod\n",
      "parsed_errors": [

      ]
    },
    {
      "name": "method_sugar.chai",
      "status": "failed",
      "time": "0.311781",
      "output": "terminate called after throwing an instance of 'std::invalid_argument'\n  what():  stod\n",
      "parsed_errors": [

      ]
    },
    {
      "name": "member_variable_access.chai",
      "status": "failed",
      "time": "0.538824",
      "output": "terminate called after throwing an instance of 'std::invalid_argument'\n  what():  stod\n",
      "parsed_errors": [

      ]
    },
    {
      "name": "memberscope.chai",
      "status": "failed",
      "time": "0.537543",
      "output": "terminate called after throwing an instance of 'std::invalid_argument'\n  what():  stod\n",
      "parsed_errors": [

      ]
    },
    {
      "name": "mmd2.chai",
      "status": "failed",
      "time": "0.306768",
      "output": "terminate called after throwing an instance of 'std::invalid_argument'\n  what():  stod\n",
      "parsed_errors": [

      ]
    },
    {
      "name": "method_missing.chai",
      "status": "failed",
      "time": "0.627696",
      "output": "terminate called after throwing an instance of 'std::invalid_argument'\n  what():  stod\n",
      "parsed_errors": [

      ]
    },
    {
      "name": "multiline.chai",
      "status": "failed",
      "time": "0.314589",
      "output": "terminate called after throwing an instance of 'std::invalid_argument'\n  what():  stod\n",
      "parsed_errors": [

      ]
    },
    {
      "name": "min.chai",
      "status": "failed",
      "time": "0.341737",
      "output": "terminate called after throwing an instance of 'std::invalid_argument'\n  what():  stod\n",
      "parsed_errors": [

      ]
    },
    {
      "name": "mmd1.chai",
      "status": "failed",
      "time": "0.3399",
      "output": "terminate called after throwing an instance of 'std::invalid_argument'\n  what():  stod\n",
      "parsed_errors": [

      ]
    },
    {
      "name": "number_suffixes.chai",
      "status": "failed",
      "time": "0.341535",
      "output": "terminate called after throwing an instance of 'std::invalid_argument'\n  what():  stod\n",
      "parsed_errors": [

      ]
    },
    {
      "name": "object_attr.chai",
      "status": "failed",
      "time": "0.338209",
      "output": "terminate called after throwing an instance of 'std::invalid_argument'\n  what():  stod\n",
      "parsed_errors": [

      ]
    },
    {
      "name": "multiline_oper.chai",
      "status": "failed",
      "time": "0.564886",
      "output": "terminate called after throwing an instance of 'std::invalid_argument'\n  what():  stod\n",
      "parsed_errors": [

      ]
    },
    {
      "name": "null_object_access.chai",
      "status": "failed",
      "time": "0.563452",
      "output": "terminate called after throwing an instance of 'std::invalid_argument'\n  what():  stod\n",
      "parsed_errors": [

      ]
    },
    {
      "name": "number_formats.chai",
      "status": "failed",
      "time": "0.560458",
      "output": "terminate called after throwing an instance of 'std::invalid_argument'\n  what():  stod\n",
      "parsed_errors": [

      ]
    },
    {
      "name": "object_constructor_guards.chai",
      "status": "failed",
      "time": "0.307361",
      "output": "terminate called after throwing an instance of 'std::invalid_argument'\n  what():  stod\n",
      "parsed_errors": [

      ]
    },
    {
      "name": "object_method_guards.chai",
      "status": "failed",
      "time": "0.31027",
      "output": "terminate called after throwing an instance of 'std::invalid_argument'\n  what():  stod\n",
      "parsed_errors": [

      ]
    },
    {
      "name": "object_attr_same_name.chai",
      "status": "failed",
      "time": "0.33797",
      "output": "terminate called after throwing an instance of 'std::invalid_argument'\n  what():  stod\n",
      "parsed_errors": [

      ]
    },
    {
      "name": "object_clone.chai",
      "status": "failed",
      "time": "0.334239",
      "output": "terminate called after throwing an instance of 'std::invalid_argument'\n  what():  stod\n",
      "parsed_errors": [

      ]
    },
    {
      "name": "operator_scoping.chai",
      "status": "failed",
      "time": "0.345785",
      "output": "terminate called after throwing an instance of 'std::invalid_argument'\n  what():  stod\n",
      "parsed_errors": [

      ]
    },
    {
      "name": "operators_float.chai",
      "status": "failed",
      "time": "0.350509",
      "output": "terminate called after throwing an instance of 'std::invalid_argument'\n  what():  stod\n",
      "parsed_errors": [

      ]
    },
    {
      "name": "odd.chai",
      "status": "failed",
      "time": "0.578717",
      "output": "terminate called after throwing an instance of 'std::invalid_argument'\n  what():  stod\n",
      "parsed_errors": [

      ]
    },
    {
      "name": "operator_overload.chai",
      "status": "failed",
      "time": "0.577519",
      "output": "terminate called after throwing an instance of 'std::invalid_argument'\n  what():  stod\n",
      "parsed_errors": [

      ]
    },
    {
      "name": "operator_overload2.chai",
      "status": "failed",
      "time": "0.574395",
      "output": "terminate called after throwing an instance of 'std::invalid_argument'\n  what():  stod\n",
      "parsed_errors": [

      ]
    },
    {
      "name": "pointer_passed_to_constructor.chai",
      "status": "failed",
      "time": "0.308608",
      "output": "terminate called after throwing an instance of 'std::invalid_argument'\n  what():  stod\n",
      "parsed_errors": [

      ]
    },
    {
      "name": "operators_int.chai",
      "status": "failed",
      "time": "0.328278",
      "output": "terminate called after throwing an instance of 'std::invalid_argument'\n  what():  stod\n",
      "parsed_errors": [

      ]
    },
    {
      "name": "pair.chai",
      "status": "failed",
      "time": "0.326045",
      "output": "terminate called after throwing an instance of 'std::invalid_argument'\n  what():  stod\n",
      "parsed_errors": [

      ]
    },
    {
      "name": "pass_by_reference.chai",
      "status": "failed",
      "time": "0.632773",
      "output": "terminate called after throwing an instance of 'std::invalid_argument'\n  what():  stod\n",
      "parsed_errors": [

      ]
    },
    {
      "name": "precedence_eq.chai",
      "status": "failed",
      "time": "0.317367",
      "output": "terminate called after throwing an instance of 'std::invalid_argument'\n  what():  stod\n",
      "parsed_errors": [

      ]
    },
    {
      "name": "precedence_1.chai",
      "status": "failed",
      "time": "0.539516",
      "output": "terminate called after throwing an instance of 'std::invalid_argument'\n  what():  stod\n",
      "parsed_errors": [

      ]
    },
    {
      "name": "precedence_2.chai",
      "status": "failed",
      "time": "0.536103",
      "output": "terminate called after throwing an instance of 'std::invalid_argument'\n  what():  stod\n",
      "parsed_errors": [

      ]
    },
    {
      "name": "precedence_3.chai",
      "status": "failed",
      "time": "0.534189",
      "output": "terminate called after throwing an instance of 'std::invalid_argument'\n  what():  stod\n",
      "parsed_errors": [

      ]
    },
    {
      "name": "range_back.chai",
      "status": "failed",
      "time": "0.305251",
      "output": "terminate called after throwing an instance of 'std::invalid_argument'\n  what():  stod\n",
      "parsed_errors": [

      ]
    },
    {
      "name": "range_contains.chai",
      "status": "failed",
      "time": "0.322461",
      "output": "terminate called after throwing an instance of 'std::invalid_argument'\n  what():  stod\n",
      "parsed_errors": [

      ]
    },
    {
      "name": "product.chai",
      "status": "failed",
      "time": "0.349071",
      "output": "terminate called after throwing an instance of 'std::invalid_argument'\n  what():  stod\n",
      "parsed_errors": [

      ]
    },
    {
      "name": "range.chai",
      "status": "failed",
      "time": "0.347105",
      "output": "terminate called after throwing an instance of 'std::invalid_argument'\n  what():  stod\n",
      "parsed_errors": [

      ]
    },
    {
      "name": "reflection_test.chai",
      "status": "failed",
      "time": "0.334004",
      "output": "terminate called after throwing an instance of 'std::invalid_argument'\n  what():  stod\n",
      "parsed_errors": [

      ]
    },
    {
      "name": "retro.chai",
      "status": "failed",
      "time": "0.344529",
      "output": "terminate called after throwing an instance of 'std::invalid_argument'\n  what():  stod\n",
      "parsed_errors": [

      ]
    },
    {
      "name": "range_find.chai",
      "status": "failed",
      "time": "0.573302",
      "output": "terminate called after throwing an instance of 'std::invalid_argument'\n  what():  stod\n",
      "parsed_errors": [

      ]
    },
    {
      "name": "range_inplace.chai",
      "status": "failed",
      "time": "0.571598",
      "output": "terminate called after throwing an instance of 'std::invalid_argument'\n  what():  stod\n",
      "parsed_errors": [

      ]
    },
    {
      "name": "reduce.chai",
      "status": "failed",
      "time": "0.568742",
      "output": "terminate called after throwing an instance of 'std::invalid_argument'\n  what():  stod\n",
      "parsed_errors": [

      ]
    },
    {
      "name": "scoping.chai",
      "status": "failed",
      "time": "0.325012",
      "output": "terminate called after throwing an instance of 'std::invalid_argument'\n  what():  stod\n",
      "parsed_errors": [

      ]
    },
    {
      "name": "retroretro.chai",
      "status": "failed",
      "time": "0.345852",
      "output": "terminate called after throwing an instance of 'std::invalid_argument'\n  what():  stod\n",
      "parsed_errors": [

      ]
    },
    {
      "name": "return.chai",
      "status": "failed",
      "time": "0.344171",
      "output": "terminate called after throwing an instance of 'std::invalid_argument'\n  what():  stod\n",
      "parsed_errors": [

      ]
    },
    {
      "name": "runtime_error.chai",
      "status": "failed",
      "time": "0.644668",
      "output": "terminate called after throwing an instance of 'std::invalid_argument'\n  what():  stod\n",
      "parsed_errors": [

      ]
    },
    {
      "name": "string_find.chai",
      "status": "failed",
      "time": "0.32316",
      "output": "terminate called after throwing an instance of 'std::invalid_argument'\n  what():  stod\n",
      "parsed_errors": [

      ]
    },
    {
      "name": "shift.chai",
      "status": "failed",
      "time": "0.556515",
      "output": "terminate called after throwing an instance of 'std::invalid_argument'\n  what():  stod\n",
      "parsed_errors": [

      ]
    },
    {
      "name": "string_charptr.chai",
      "status": "failed",
      "time": "0.553221",
      "output": "terminate called after throwing an instance of 'std::invalid_argument'\n  what():  stod\n",
      "parsed_errors": [

      ]
    },
    {
      "name": "string_concat.chai",
      "status": "failed",
      "time": "0.548763",
      "output": "terminate called after throwing an instance of 'std::invalid_argument'\n  what():  stod\n",
      "parsed_errors": [

      ]
    },
    {
      "name": "string_find_last_of.chai",
      "status": "failed",
      "time": "0.318733",
      "output": "terminate called after throwing an instance of 'std::invalid_argument'\n  what():  stod\n",
      "parsed_errors": [

      ]
    },
    {
      "name": "string_find_first_not_of.chai",
      "status": "failed",
      "time": "0.338923",
      "output": "terminate called after throwing an instance of 'std::invalid_argument'\n  what():  stod\n",
      "parsed_errors": [

      ]
    },
    {
      "name": "string_find_first_of.chai",
      "status": "failed",
      "time": "0.337113",
      "output": "terminate called after throwing an instance of 'std::invalid_argument'\n  what():  stod\n",
      "parsed_errors": [

      ]
    },
    {
      "name": "string_find_last_not_of.chai",
      "status": "failed",
      "time": "0.63916",
      "output": "terminate called after throwing an instance of 'std::invalid_argument'\n  what():  stod\n",
      "parsed_errors": [

      ]
    },
    {
      "name": "string_size.chai",
      "status": "failed",
      "time": "0.316884",
      "output": "terminate called after throwing an instance of 'std::invalid_argument'\n  what():  stod\n",
      "parsed_errors": [

      ]
    },
    {
      "name": "string_init.chai",
      "status": "failed",
      "time": "0.431089",
      "output": "terminate called after throwing an instance of 'std::invalid_argument'\n  what():  stod\n",
      "parsed_errors": [

      ]
    },
    {
      "name": "string_literal_access.chai",
      "status": "failed",
      "time": "0.429548",
      "output": "terminate called after throwing an instance of 'std::invalid_argument'\n  what():  stod\n",
      "parsed_errors": [

      ]
    },
    {
      "name": "string_rfind.chai",
      "status": "failed",
      "time": "0.427936",
      "output": "terminate called after throwing an instance of 'std::invalid_argument'\n  what():  stod\n",
      "parsed_errors": [

      ]
    },
    {
      "name": "switch_break.chai",
      "status": "failed",
      "time": "0.31884",
      "output": "terminate called after throwing an instance of 'std::invalid_argument'\n  what():  stod\n",
      "parsed_errors": [

      ]
    },
    {
      "name": "string_substr.chai",
      "status": "failed",
      "time": "0.333344",
      "output": "terminate called after throwing an instance of 'std::invalid_argument'\n  what():  stod\n",
      "parsed_errors": [

      ]
    },
    {
      "name": "sum.chai",
      "status": "failed",
      "time": "0.644736",
      "output": "terminate called after throwing an instance of 'std::invalid_argument'\n  what():  stod\n",
      "parsed_errors": [

      ]
    },
    {
      "name": "switch_default.chai",
      "status": "failed",
      "time": "0.641677",
      "output": "terminate called after throwing an instance of 'std::invalid_argument'\n  what():  stod\n",
      "parsed_errors": [

      ]
    },
    {
      "name": "system_introspection.chai",
      "status": "failed",
      "time": "0.319061",
      "output": "terminate called after throwing an instance of 'std::invalid_argument'\n  what():  stod\n",
      "parsed_errors": [

      ]
    },
    {
      "name": "switch_empty.chai",
      "status": "failed",
      "time": "0.435925",
      "output": "terminate called after throwing an instance of 'std::invalid_argument'\n  what():  stod\n",
      "parsed_errors": [

      ]
    },
    {
      "name": "switch_fallthru.chai",
      "status": "failed",
      "time": "0.434265",
      "output": "terminate called after throwing an instance of 'std::invalid_argument'\n  what():  stod\n",
      "parsed_errors": [

      ]
    },
    {
      "name": "switch_fallthru_and_break.chai",
      "status": "failed",
      "time": "0.43227",
      "output": "terminate called after throwing an instance of 'std::invalid_argument'\n  what():  stod\n",
      "parsed_errors": [

      ]
    },
    {
      "name": "temporary_lifetime.chai",
      "status": "failed",
      "time": "0.328514",
      "output": "terminate called after throwing an instance of 'std::invalid_argument'\n  what():  stod\n",
      "parsed_errors": [

      ]
    },
    {
      "name": "take.chai",
      "status": "failed",
      "time": "0.346185",
      "output": "terminate called after throwing an instance of 'std::invalid_argument'\n  what():  stod\n",
      "parsed_errors": [

      ]
    },
    {
      "name": "take_while.chai",
      "status": "failed",
      "time": "0.646658",
      "output": "terminate called after throwing an instance of 'std::invalid_argument'\n  what():  stod\n",
      "parsed_errors": [

      ]
    },
    {
      "name": "ternary_condition.chai",
      "status": "failed",
      "time": "0.641639",
      "output": "terminate called after throwing an instance of 'std::invalid_argument'\n  what():  stod\n",
      "parsed_errors": [

      ]
    },
    {
      "name": "user_defined_conversions_2.chai",
      "status": "failed",
      "time": "0.314949",
      "output": "terminate called after throwing an instance of 'std::invalid_argument'\n  what():  stod\n",
      "parsed_errors": [

      ]
    },
    {
      "name": "type_info.chai",
      "status": "failed",
      "time": "0.53697",
      "output": "terminate called after throwing an instance of 'std::invalid_argument'\n  what():  stod\n",
      "parsed_errors": [

      ]
    },
    {
      "name": "use.chai",
      "status": "failed",
      "time": "0.534569",
      "output": "terminate called after throwing an instance of 'std::invalid_argument'\n  what():  stod\n",
      "parsed_errors": [

      ]
    },
    {
      "name": "user_defined_conversions.chai",
      "status": "failed",
      "time": "0.531998",
      "output": "terminate called after throwing an instance of 'std::invalid_argument'\n  what():  stod\n",
      "parsed_errors": [

      ]
    },
    {
      "name": "variable_redefinition.chai",
      "status": "failed",
      "time": "0.337624",
      "output": "terminate called after throwing an instance of 'std::invalid_argument'\n  what():  stod\n",
      "parsed_errors": [

      ]
    },
    {
      "name": "vector_access.chai",
      "status": "failed",
      "time": "0.343528",
      "output": "terminate called after throwing an instance of 'std::invalid_argument'\n  what():  stod\n",
      "parsed_errors": [

      ]
    },
    {
      "name": "var_decl.chai",
      "status": "failed",
      "time": "0.3525",
      "output": "terminate called after throwing an instance of 'std::invalid_argument'\n  what():  stod\n",
      "parsed_errors": [

      ]
    },
    {
      "name": "var_ref_decl.chai",
      "status": "failed",
      "time": "0.553998",
      "output": "terminate called after throwing an instance of 'std::invalid_argument'\n  what():  stod\n",
      "parsed_errors": [

      ]
    },
    {
      "name": "vector_literal_acccess.chai",
      "status": "failed",
      "time": "0.322606",
      "output": "terminate called after throwing an instance of 'std::invalid_argument'\n  what():  stod\n",
      "parsed_errors": [

      ]
    },
    {
      "name": "vector_inplace_init.chai",
      "status": "failed",
      "time": "0.437681",
      "output": "terminate called after throwing an instance of 'std::invalid_argument'\n  what():  stod\n",
      "parsed_errors": [

      ]
    },
    {
      "name": "vector_insert_at.chai",
      "status": "failed",
      "time": "0.436131",
      "output": "terminate called after throwing an instance of 'std::invalid_argument'\n  what():  stod\n",
      "parsed_errors": [

      ]
    },
    {
      "name": "vector_push_back.chai",
      "status": "failed",
      "time": "0.350469",
      "output": "terminate called after throwing an instance of 'std::invalid_argument'\n  what():  stod\n",
      "parsed_errors": [

      ]
    },
    {
      "name": "vector_erase_at.chai",
      "status": "failed",
      "time": "0.685633",
      "output": "terminate called after throwing an instance of 'std::invalid_argument'\n  what():  stod\n",
      "parsed_errors": [

      ]
    },
    {
      "name": "vector_of_suffixed_numbers.chai",
      "status": "failed",
      "time": "0.369877",
      "output": "terminate called after throwing an instance of 'std::invalid_argument'\n  what():  stod\n",
      "parsed_errors": [

      ]
    },
    {
      "name": "vector_of_one.chai",
      "status": "failed",
      "time": "0.575761",
      "output": "terminate called after throwing an instance of 'std::invalid_argument'\n  what():  stod\n",
      "parsed_errors": [

      ]
    },
    {
      "name": "vector_paren_literal_access.chai",
      "status": "failed",
      "time": "0.571236",
      "output": "terminate called after throwing an instance of 'std::invalid_argument'\n  what():  stod\n",
      "parsed_errors": [

      ]
    },
    {
      "name": "C++11 Lambdas Can Be Registered",
      "status": "failed",
      "time": "0.306483",
      "output": "\n~~~~~~~~~~~~~~~~~~~~~~~~~~~~~~~~~~~~~~~~~~~~~~~~~~~~~~~~~~~~~~~~~~~~~~~~~~~~~~~\ncompiled_tests is a Catch v1.1 b1 host application.\nRun with -? for options\n\n-------------------------------------------------------------------------------\nC++11 Lambdas Can Be Registered\n-------------------------------------------------------------------------------\n/home/jason/CIWork/ci_runs/CS-d77921f1b5-x86_64-C3.5TS/unittests/compiled_tests.cpp:33\n...............................................................................\n\n/home/jason/CIWork/ci_runs/CS-d77921f1b5-x86_64-C3.5TS/unittests/compiled_tests.cpp:33: FAILED:\ndue to unexpected exception with message:\n  stod\n\n===============================================================================\ntest cases: 1 | 1 failed\nassertions: 1 | 1 failed\n\n",
      "parsed_errors": [
        {
          "filename": "unittests/compiled_tests.cpp",
          "linenumber": "33",
          "colnumber": 0,
          "messagetype": "error",
          "message": "FAILED:"
        }
      ]
    },
    {
      "name": "vector_push_empty.chai",
      "status": "failed",
      "time": "0.432512",
      "output": "terminate called after throwing an instance of 'std::invalid_argument'\n  what():  stod\n",
      "parsed_errors": [

      ]
    },
    {
      "name": "zip.chai",
      "status": "failed",
      "time": "0.429218",
      "output": "terminate called after throwing an instance of 'std::invalid_argument'\n  what():  stod\n",
      "parsed_errors": [

      ]
    },
    {
      "name": "ChaiScript can be created and destroyed on heap",
      "status": "failed",
      "time": "0.194535",
      "output": "\n~~~~~~~~~~~~~~~~~~~~~~~~~~~~~~~~~~~~~~~~~~~~~~~~~~~~~~~~~~~~~~~~~~~~~~~~~~~~~~~\ncompiled_tests is a Catch v1.1 b1 host application.\nRun with -? for options\n\n-------------------------------------------------------------------------------\nChaiScript can be created and destroyed on heap\n-------------------------------------------------------------------------------\n/home/jason/CIWork/ci_runs/CS-d77921f1b5-x86_64-C3.5TS/unittests/compiled_tests.cpp:94\n...............................................................................\n\n/home/jason/CIWork/ci_runs/CS-d77921f1b5-x86_64-C3.5TS/unittests/compiled_tests.cpp:94: FAILED:\ndue to unexpected exception with message:\n  stod\n\n===============================================================================\ntest cases: 1 | 1 failed\nassertions: 1 | 1 failed\n\n",
      "parsed_errors": [
        {
          "filename": "unittests/compiled_tests.cpp",
          "linenumber": "94",
          "colnumber": 0,
          "messagetype": "error",
          "message": "FAILED:"
        }
      ]
    },
    {
      "name": "Test automatic arithmetic conversions",
      "status": "failed",
      "time": "0.190081",
      "output": "\n~~~~~~~~~~~~~~~~~~~~~~~~~~~~~~~~~~~~~~~~~~~~~~~~~~~~~~~~~~~~~~~~~~~~~~~~~~~~~~~\ncompiled_tests is a Catch v1.1 b1 host application.\nRun with -? for options\n\n-------------------------------------------------------------------------------\nTest automatic arithmetic conversions\n-------------------------------------------------------------------------------\n/home/jason/CIWork/ci_runs/CS-d77921f1b5-x86_64-C3.5TS/unittests/compiled_tests.cpp:126\n...............................................................................\n\n/home/jason/CIWork/ci_runs/CS-d77921f1b5-x86_64-C3.5TS/unittests/compiled_tests.cpp:126: FAILED:\ndue to unexpected exception with message:\n  stod\n\n===============================================================================\ntest cases: 1 | 1 failed\nassertions: 1 | 1 failed\n\n",
      "parsed_errors": [
        {
          "filename": "unittests/compiled_tests.cpp",
          "linenumber": "126",
          "colnumber": 0,
          "messagetype": "error",
          "message": "FAILED:"
        }
      ]
    },
    {
      "name": "zip_with.chai",
      "status": "failed",
      "time": "0.511848",
      "output": "terminate called after throwing an instance of 'std::invalid_argument'\n  what():  stod\n",
      "parsed_errors": [

      ]
    },
    {
      "name": "Dynamic_Object attributes can be shared with C++",
      "status": "failed",
      "time": "0.202625",
      "output": "\n~~~~~~~~~~~~~~~~~~~~~~~~~~~~~~~~~~~~~~~~~~~~~~~~~~~~~~~~~~~~~~~~~~~~~~~~~~~~~~~\ncompiled_tests is a Catch v1.1 b1 host application.\nRun with -? for options\n\n-------------------------------------------------------------------------------\nDynamic_Object attributes can be shared with C++\n-------------------------------------------------------------------------------\n/home/jason/CIWork/ci_runs/CS-d77921f1b5-x86_64-C3.5TS/unittests/compiled_tests.cpp:52\n...............................................................................\n\n/home/jason/CIWork/ci_runs/CS-d77921f1b5-x86_64-C3.5TS/unittests/compiled_tests.cpp:52: FAILED:\ndue to unexpected exception with message:\n  stod\n\n===============================================================================\ntest cases: 1 | 1 failed\nassertions: 1 | 1 failed\n\n",
      "parsed_errors": [
        {
          "filename": "unittests/compiled_tests.cpp",
          "linenumber": "52",
          "colnumber": 0,
          "messagetype": "error",
          "message": "FAILED:"
        }
      ]
    },
    {
      "name": "Function objects can be created from chaiscript functions",
      "status": "failed",
      "time": "0.255439",
      "output": "\n~~~~~~~~~~~~~~~~~~~~~~~~~~~~~~~~~~~~~~~~~~~~~~~~~~~~~~~~~~~~~~~~~~~~~~~~~~~~~~~\ncompiled_tests is a Catch v1.1 b1 host application.\nRun with -? for options\n\n-------------------------------------------------------------------------------\nFunction objects can be created from chaiscript functions\n-------------------------------------------------------------------------------\n/home/jason/CIWork/ci_runs/CS-d77921f1b5-x86_64-C3.5TS/unittests/compiled_tests.cpp:79\n...............................................................................\n\n/home/jason/CIWork/ci_runs/CS-d77921f1b5-x86_64-C3.5TS/unittests/compiled_tests.cpp:79: FAILED:\ndue to unexpected exception with message:\n  stod\n\n===============================================================================\ntest cases: 1 | 1 failed\nassertions: 1 | 1 failed\n\n",
      "parsed_errors": [
        {
          "filename": "unittests/compiled_tests.cpp",
          "linenumber": "79",
          "colnumber": 0,
          "messagetype": "error",
          "message": "FAILED:"
        }
      ]
    },
    {
      "name": "Throw int or double",
      "status": "failed",
      "time": "0.28583",
      "output": "\n~~~~~~~~~~~~~~~~~~~~~~~~~~~~~~~~~~~~~~~~~~~~~~~~~~~~~~~~~~~~~~~~~~~~~~~~~~~~~~~\ncompiled_tests is a Catch v1.1 b1 host application.\nRun with -? for options\n\n-------------------------------------------------------------------------------\nThrow int or double\n-------------------------------------------------------------------------------\n/home/jason/CIWork/ci_runs/CS-d77921f1b5-x86_64-C3.5TS/unittests/compiled_tests.cpp:192\n...............................................................................\n\n/home/jason/CIWork/ci_runs/CS-d77921f1b5-x86_64-C3.5TS/unittests/compiled_tests.cpp:192: FAILED:\ndue to unexpected exception with message:\n  stod\n\n===============================================================================\ntest cases: 1 | 1 failed\nassertions: 1 | 1 failed\n\n",
      "parsed_errors": [
        {
          "filename": "unittests/compiled_tests.cpp",
          "linenumber": "192",
          "colnumber": 0,
          "messagetype": "error",
          "message": "FAILED:"
        }
      ]
    },
    {
      "name": "No unexpected exceptions leak",
      "status": "failed",
      "time": "0.263657",
      "output": "\n~~~~~~~~~~~~~~~~~~~~~~~~~~~~~~~~~~~~~~~~~~~~~~~~~~~~~~~~~~~~~~~~~~~~~~~~~~~~~~~\ncompiled_tests is a Catch v1.1 b1 host application.\nRun with -? for options\n\n-------------------------------------------------------------------------------\nNo unexpected exceptions leak\n-------------------------------------------------------------------------------\n/home/jason/CIWork/ci_runs/CS-d77921f1b5-x86_64-C3.5TS/unittests/compiled_tests.cpp:253\n...............................................................................\n\n/home/jason/CIWork/ci_runs/CS-d77921f1b5-x86_64-C3.5TS/unittests/compiled_tests.cpp:253: FAILED:\ndue to unexpected exception with message:\n  stod\n\n===============================================================================\ntest cases: 1 | 1 failed\nassertions: 1 | 1 failed\n\n",
      "parsed_errors": [
        {
          "filename": "unittests/compiled_tests.cpp",
          "linenumber": "253",
          "colnumber": 0,
          "messagetype": "error",
          "message": "FAILED:"
        }
      ]
    },
    {
      "name": "Throw unhandled type",
      "status": "failed",
      "time": "0.279789",
      "output": "\n~~~~~~~~~~~~~~~~~~~~~~~~~~~~~~~~~~~~~~~~~~~~~~~~~~~~~~~~~~~~~~~~~~~~~~~~~~~~~~~\ncompiled_tests is a Catch v1.1 b1 host application.\nRun with -? for options\n\n-------------------------------------------------------------------------------\nThrow unhandled type\n-------------------------------------------------------------------------------\n/home/jason/CIWork/ci_runs/CS-d77921f1b5-x86_64-C3.5TS/unittests/compiled_tests.cpp:224\n...............................................................................\n\n/home/jason/CIWork/ci_runs/CS-d77921f1b5-x86_64-C3.5TS/unittests/compiled_tests.cpp:224: FAILED:\ndue to unexpected exception with message:\n  stod\n\n===============================================================================\ntest cases: 1 | 1 failed\nassertions: 1 | 1 failed\n\n",
      "parsed_errors": [
        {
          "filename": "unittests/compiled_tests.cpp",
          "linenumber": "224",
          "colnumber": 0,
          "messagetype": "error",
          "message": "FAILED:"
        }
      ]
    },
    {
      "name": "Throw a runtime_error",
      "status": "failed",
      "time": "0.281986",
      "output": "\n~~~~~~~~~~~~~~~~~~~~~~~~~~~~~~~~~~~~~~~~~~~~~~~~~~~~~~~~~~~~~~~~~~~~~~~~~~~~~~~\ncompiled_tests is a Catch v1.1 b1 host application.\nRun with -? for options\n\n-------------------------------------------------------------------------------\nThrow a runtime_error\n-------------------------------------------------------------------------------\n/home/jason/CIWork/ci_runs/CS-d77921f1b5-x86_64-C3.5TS/unittests/compiled_tests.cpp:204\n...............................................................................\n\n/home/jason/CIWork/ci_runs/CS-d77921f1b5-x86_64-C3.5TS/unittests/compiled_tests.cpp:204: FAILED:\ndue to unexpected exception with message:\n  stod\n\n===============================================================================\ntest cases: 1 | 1 failed\nassertions: 1 | 1 failed\n\n",
      "parsed_errors": [
        {
          "filename": "unittests/compiled_tests.cpp",
          "linenumber": "204",
          "colnumber": 0,
          "messagetype": "error",
          "message": "FAILED:"
        }
      ]
    },
    {
      "name": "Generic exception handling with C++",
      "status": "failed",
      "time": "0.418699",
      "output": "\n~~~~~~~~~~~~~~~~~~~~~~~~~~~~~~~~~~~~~~~~~~~~~~~~~~~~~~~~~~~~~~~~~~~~~~~~~~~~~~~\ncompiled_tests is a Catch v1.1 b1 host application.\nRun with -? for options\n\n-------------------------------------------------------------------------------\nGeneric exception handling with C++\n-------------------------------------------------------------------------------\n/home/jason/CIWork/ci_runs/CS-d77921f1b5-x86_64-C3.5TS/unittests/compiled_tests.cpp:167\n...............................................................................\n\n/home/jason/CIWork/ci_runs/CS-d77921f1b5-x86_64-C3.5TS/unittests/compiled_tests.cpp:167: FAILED:\ndue to unexpected exception with message:\n  stod\n\n===============================================================================\ntest cases: 1 | 1 failed\nassertions: 1 | 1 failed\n\n",
      "parsed_errors": [
        {
          "filename": "unittests/compiled_tests.cpp",
          "linenumber": "167",
          "colnumber": 0,
          "messagetype": "error",
          "message": "FAILED:"
        }
      ]
    },
    {
      "name": "Throw an int",
      "status": "failed",
      "time": "0.41671",
      "output": "\n~~~~~~~~~~~~~~~~~~~~~~~~~~~~~~~~~~~~~~~~~~~~~~~~~~~~~~~~~~~~~~~~~~~~~~~~~~~~~~~\ncompiled_tests is a Catch v1.1 b1 host application.\nRun with -? for options\n\n-------------------------------------------------------------------------------\nThrow an int\n-------------------------------------------------------------------------------\n/home/jason/CIWork/ci_runs/CS-d77921f1b5-x86_64-C3.5TS/unittests/compiled_tests.cpp:180\n...............................................................................\n\n/home/jason/CIWork/ci_runs/CS-d77921f1b5-x86_64-C3.5TS/unittests/compiled_tests.cpp:180: FAILED:\ndue to unexpected exception with message:\n  stod\n\n===============================================================================\ntest cases: 1 | 1 failed\nassertions: 1 | 1 failed\n\n",
      "parsed_errors": [
        {
          "filename": "unittests/compiled_tests.cpp",
          "linenumber": "180",
          "colnumber": 0,
          "messagetype": "error",
          "message": "FAILED:"
        }
      ]
    },
    {
      "name": "Functor cast",
      "status": "failed",
      "time": "0.21869",
      "output": "\n~~~~~~~~~~~~~~~~~~~~~~~~~~~~~~~~~~~~~~~~~~~~~~~~~~~~~~~~~~~~~~~~~~~~~~~~~~~~~~~\ncompiled_tests is a Catch v1.1 b1 host application.\nRun with -? for options\n\n-------------------------------------------------------------------------------\nFunctor cast\n-------------------------------------------------------------------------------\n/home/jason/CIWork/ci_runs/CS-d77921f1b5-x86_64-C3.5TS/unittests/compiled_tests.cpp:339\n...............................................................................\n\n/home/jason/CIWork/ci_runs/CS-d77921f1b5-x86_64-C3.5TS/unittests/compiled_tests.cpp:339: FAILED:\ndue to unexpected exception with message:\n  stod\n\n===============================================================================\ntest cases: 1 | 1 failed\nassertions: 1 | 1 failed\n\n",
      "parsed_errors": [
        {
          "filename": "unittests/compiled_tests.cpp",
          "linenumber": "339",
          "colnumber": 0,
          "messagetype": "error",
          "message": "FAILED:"
        }
      ]
    },
    {
      "name": "Test lookup of type names",
      "status": "failed",
      "time": "0.235738",
      "output": "\n~~~~~~~~~~~~~~~~~~~~~~~~~~~~~~~~~~~~~~~~~~~~~~~~~~~~~~~~~~~~~~~~~~~~~~~~~~~~~~~\ncompiled_tests is a Catch v1.1 b1 host application.\nRun with -? for options\n\n-------------------------------------------------------------------------------\nTest lookup of type names\n-------------------------------------------------------------------------------\n/home/jason/CIWork/ci_runs/CS-d77921f1b5-x86_64-C3.5TS/unittests/compiled_tests.cpp:428\n...............................................................................\n\n/home/jason/CIWork/ci_runs/CS-d77921f1b5-x86_64-C3.5TS/unittests/compiled_tests.cpp:428: FAILED:\ndue to unexpected exception with message:\n  stod\n\n===============================================================================\ntest cases: 1 | 1 failed\nassertions: 1 | 1 failed\n\n",
      "parsed_errors": [
        {
          "filename": "unittests/compiled_tests.cpp",
          "linenumber": "428",
          "colnumber": 0,
          "messagetype": "error",
          "message": "FAILED:"
        }
      ]
    },
    {
      "name": "Set and restore chai state",
      "status": "failed",
      "time": "0.240304",
      "output": "\n~~~~~~~~~~~~~~~~~~~~~~~~~~~~~~~~~~~~~~~~~~~~~~~~~~~~~~~~~~~~~~~~~~~~~~~~~~~~~~~\ncompiled_tests is a Catch v1.1 b1 host application.\nRun with -? for options\n\n-------------------------------------------------------------------------------\nSet and restore chai state\n-------------------------------------------------------------------------------\n/home/jason/CIWork/ci_runs/CS-d77921f1b5-x86_64-C3.5TS/unittests/compiled_tests.cpp:359\n...............................................................................\n\n/home/jason/CIWork/ci_runs/CS-d77921f1b5-x86_64-C3.5TS/unittests/compiled_tests.cpp:359: FAILED:\ndue to unexpected exception with message:\n  stod\n\n===============================================================================\ntest cases: 1 | 1 failed\nassertions: 1 | 1 failed\n\n",
      "parsed_errors": [
        {
          "filename": "unittests/compiled_tests.cpp",
          "linenumber": "359",
          "colnumber": 0,
          "messagetype": "error",
          "message": "FAILED:"
        }
      ]
    },
    {
      "name": "Short comparison with int",
      "status": "failed",
      "time": "0.237519",
      "output": "\n~~~~~~~~~~~~~~~~~~~~~~~~~~~~~~~~~~~~~~~~~~~~~~~~~~~~~~~~~~~~~~~~~~~~~~~~~~~~~~~\ncompiled_tests is a Catch v1.1 b1 host application.\nRun with -? for options\n\n-------------------------------------------------------------------------------\nShort comparison with int\n-------------------------------------------------------------------------------\n/home/jason/CIWork/ci_runs/CS-d77921f1b5-x86_64-C3.5TS/unittests/compiled_tests.cpp:405\n...............................................................................\n\n/home/jason/CIWork/ci_runs/CS-d77921f1b5-x86_64-C3.5TS/unittests/compiled_tests.cpp:405: FAILED:\ndue to unexpected exception with message:\n  stod\n\n===============================================================================\ntest cases: 1 | 1 failed\nassertions: 1 | 1 failed\n\n",
      "parsed_errors": [
        {
          "filename": "unittests/compiled_tests.cpp",
          "linenumber": "405",
          "colnumber": 0,
          "messagetype": "error",
          "message": "FAILED:"
        }
      ]
    },
    {
      "name": "Function ordering",
      "status": "failed",
      "time": "0.294707",
      "output": "\n~~~~~~~~~~~~~~~~~~~~~~~~~~~~~~~~~~~~~~~~~~~~~~~~~~~~~~~~~~~~~~~~~~~~~~~~~~~~~~~\ncompiled_tests is a Catch v1.1 b1 host application.\nRun with -? for options\n\n-------------------------------------------------------------------------------\nFunction ordering\n-------------------------------------------------------------------------------\n/home/jason/CIWork/ci_runs/CS-d77921f1b5-x86_64-C3.5TS/unittests/compiled_tests.cpp:316\n...............................................................................\n\n/home/jason/CIWork/ci_runs/CS-d77921f1b5-x86_64-C3.5TS/unittests/compiled_tests.cpp:316: FAILED:\ndue to unexpected exception with message:\n  stod\n\n===============================================================================\ntest cases: 1 | 1 failed\nassertions: 1 | 1 failed\n\n",
      "parsed_errors": [
        {
          "filename": "unittests/compiled_tests.cpp",
          "linenumber": "316",
          "colnumber": 0,
          "messagetype": "error",
          "message": "FAILED:"
        }
      ]
    },
    {
      "name": "Object lifetime test 2",
      "status": "failed",
      "time": "0.338755",
      "output": "\n~~~~~~~~~~~~~~~~~~~~~~~~~~~~~~~~~~~~~~~~~~~~~~~~~~~~~~~~~~~~~~~~~~~~~~~~~~~~~~~\ncompiled_tests is a Catch v1.1 b1 host application.\nRun with -? for options\n\n-------------------------------------------------------------------------------\nObject lifetime test 2\n-------------------------------------------------------------------------------\n/home/jason/CIWork/ci_runs/CS-d77921f1b5-x86_64-C3.5TS/unittests/compiled_tests.cpp:697\n...............................................................................\n\n/home/jason/CIWork/ci_runs/CS-d77921f1b5-x86_64-C3.5TS/unittests/compiled_tests.cpp:697: FAILED:\ndue to unexpected exception with message:\n  stod\n\n===============================================================================\ntest cases: 1 | 1 failed\nassertions: 1 | 1 failed\n\n",
      "parsed_errors": [
        {
          "filename": "unittests/compiled_tests.cpp",
          "linenumber": "697",
          "colnumber": 0,
          "messagetype": "error",
          "message": "FAILED:"
        }
      ]
    },
    {
      "name": "Object lifetime tests",
      "status": "failed",
      "time": "0.350033",
      "output": "\n~~~~~~~~~~~~~~~~~~~~~~~~~~~~~~~~~~~~~~~~~~~~~~~~~~~~~~~~~~~~~~~~~~~~~~~~~~~~~~~\ncompiled_tests is a Catch v1.1 b1 host application.\nRun with -? for options\n\n-------------------------------------------------------------------------------\nObject lifetime tests\n-------------------------------------------------------------------------------\n/home/jason/CIWork/ci_runs/CS-d77921f1b5-x86_64-C3.5TS/unittests/compiled_tests.cpp:637\n...............................................................................\n\n/home/jason/CIWork/ci_runs/CS-d77921f1b5-x86_64-C3.5TS/unittests/compiled_tests.cpp:637: FAILED:\ndue to unexpected exception with message:\n  stod\n\n===============================================================================\ntest cases: 1 | 1 failed\nassertions: 1 | 1 failed\n\n",
      "parsed_errors": [
        {
          "filename": "unittests/compiled_tests.cpp",
          "linenumber": "637",
          "colnumber": 0,
          "messagetype": "error",
          "message": "FAILED:"
        }
      ]
    },
    {
      "name": "Object copy counts",
      "status": "failed",
      "time": "0.352374",
      "output": "\n~~~~~~~~~~~~~~~~~~~~~~~~~~~~~~~~~~~~~~~~~~~~~~~~~~~~~~~~~~~~~~~~~~~~~~~~~~~~~~~\ncompiled_tests is a Catch v1.1 b1 host application.\nRun with -? for options\n\n-------------------------------------------------------------------------------\nObject copy counts\n-------------------------------------------------------------------------------\n/home/jason/CIWork/ci_runs/CS-d77921f1b5-x86_64-C3.5TS/unittests/compiled_tests.cpp:581\n...............................................................................\n\n/home/jason/CIWork/ci_runs/CS-d77921f1b5-x86_64-C3.5TS/unittests/compiled_tests.cpp:581: FAILED:\ndue to unexpected exception with message:\n  stod\n\n===============================================================================\ntest cases: 1 | 1 failed\nassertions: 1 | 1 failed\n\n",
      "parsed_errors": [
        {
          "filename": "unittests/compiled_tests.cpp",
          "linenumber": "581",
          "colnumber": 0,
          "messagetype": "error",
          "message": "FAILED:"
        }
      ]
    },
    {
      "name": "Simultaneous ChaiScript tests",
      "status": "failed",
      "time": "0.378283",
      "output": "\n~~~~~~~~~~~~~~~~~~~~~~~~~~~~~~~~~~~~~~~~~~~~~~~~~~~~~~~~~~~~~~~~~~~~~~~~~~~~~~~\ncompiled_tests is a Catch v1.1 b1 host application.\nRun with -? for options\n\n-------------------------------------------------------------------------------\nSimultaneous ChaiScript tests\n-------------------------------------------------------------------------------\n/home/jason/CIWork/ci_runs/CS-d77921f1b5-x86_64-C3.5TS/unittests/compiled_tests.cpp:454\n...............................................................................\n\n/home/jason/CIWork/ci_runs/CS-d77921f1b5-x86_64-C3.5TS/unittests/compiled_tests.cpp:454: FAILED:\ndue to unexpected exception with message:\n  stod\n\n===============================================================================\ntest cases: 1 | 1 failed\nassertions: 1 | 1 failed\n\n",
      "parsed_errors": [
        {
          "filename": "unittests/compiled_tests.cpp",
          "linenumber": "454",
          "colnumber": 0,
          "messagetype": "error",
          "message": "FAILED:"
        }
      ]
    },
    {
      "name": "Utility_Test utility class wrapper",
      "status": "failed",
      "time": "0.376332",
      "output": "\n~~~~~~~~~~~~~~~~~~~~~~~~~~~~~~~~~~~~~~~~~~~~~~~~~~~~~~~~~~~~~~~~~~~~~~~~~~~~~~~\ncompiled_tests is a Catch v1.1 b1 host application.\nRun with -? for options\n\n-------------------------------------------------------------------------------\nUtility_Test utility class wrapper\n-------------------------------------------------------------------------------\n/home/jason/CIWork/ci_runs/CS-d77921f1b5-x86_64-C3.5TS/unittests/compiled_tests.cpp:488\n...............................................................................\n\n/home/jason/CIWork/ci_runs/CS-d77921f1b5-x86_64-C3.5TS/unittests/compiled_tests.cpp:488: FAILED:\ndue to unexpected exception with message:\n  stod\n\n===============================================================================\ntest cases: 1 | 1 failed\nassertions: 1 | 1 failed\n\n",
      "parsed_errors": [
        {
          "filename": "unittests/compiled_tests.cpp",
          "linenumber": "488",
          "colnumber": 0,
          "messagetype": "error",
          "message": "FAILED:"
        }
      ]
    },
    {
      "name": "Multithreaded_Test",
      "status": "failed",
      "time": "0.291792",
      "output": "terminate called after throwing an instance of 'std::invalid_argument'\n  what():  stod\n",
      "parsed_errors": [

      ]
    },
    {
      "name": "Type_Info_Test",
      "status": "passed",
      "time": "0.304558",
      "output": "Size of Type_Info 24\n",
      "parsed_errors": [

      ]
    },
    {
      "name": "C_Linkage_Test",
      "status": "failed",
      "time": "0.310656",
      "output": "terminate called after throwing an instance of 'std::invalid_argument'\n  what():  stod\n",
      "parsed_errors": [

      ]
    },
    {
      "name": "Boxed_Cast_Test",
      "status": "passed",
      "time": "0.734397",
      "output": null,
      "parsed_errors": [

      ]
    },
    {
      "name": "Integer_Literal_Test",
      "status": "failed",
      "time": "0.408109",
      "output": "terminate called after throwing an instance of 'std::invalid_argument'\n  what():  stod\n",
      "parsed_errors": [

      ]
    },
    {
      "name": "MultiFile_Test",
      "status": "failed",
      "time": "0.204869",
      "output": "terminate called after throwing an instance of 'std::invalid_argument'\n  what():  stod\n",
      "parsed_errors": [

      ]
    }
  ],
  "failure": null,
  "package_results": [

  ]
}

